Workbook

Sheet Exposure
A1: Step 0:premium indexation
A3: Exposure measure
B6: Year | C6: Premium | E6: Number of risks | G6: Average premium | H6: Premium index | I6: indexed Premium
B7: 2016 | C7: 142145345 | E7: 124123 | G7: =$C7/$E7 -> 1145.1975 | H7: =$G7/$G$7*100 -> 100 | I7: =$C7*$H$18/$H7 -> 1.9165068e+08
B8: =B7+1 -> 2017 | C8: 143456190 | E8: 124487 | G8: =$C8/$E8 -> 1152.3789 | H8: =$G8/$G$7*100 -> 100.62709 | I8: =$C8*$H$18/$H8 -> 1.9221271e+08
B9: =B8+1 -> 2018 | C9: 1.4778857e+08 | E9: 125731.87 | G9: =$C9/$E9 -> 1175.4265 | H9: =$G9/$G$7*100 -> 102.63963 | I9: =$C9*$H$18/$H9 -> 1.9413484e+08
B10: =B9+1 -> 2019 | C10: 1.5526667e+08 | E10: 128246.51 | G10: =$C10/$E10 -> 1210.6893 | H10: =$G10/$G$7*100 -> 105.71882 | I10: =$C10*$H$18/$H10 -> 1.9801754e+08
B11: =B10+1 -> 2020 | C11: 1.6312316e+08 | E11: 132093.9 | G11: =$C11/$E11 -> 1234.903 | H11: =$G11/$G$7*100 -> 107.8332 | I11: =$C11*$H$18/$H11 -> 2.0395806e+08
B12: =B11+1 -> 2021 | C12: 1.6804948e+08 | E12: 134735.78 | G12: =$C12/$E12 -> 1247.2521 | H12: =$G12/$G$7*100 -> 108.91153 | I12: =$C12*$H$18/$H12 -> 2.0803722e+08
B13: =B12+1 -> 2022 | C13: 1.7655279e+08 | E13: 138777.85 | G13: =$C13/$E13 -> 1272.1971 | H13: =$G13/$G$7*100 -> 111.08976 | I13: =$C13*$H$18/$H13 -> 2.1427834e+08
B14: =B13+1 -> 2023 | C14: 1.801015e+08 | E14: 140165.63 | G14: =$C14/$E14 -> 1284.9191 | H14: =$G14/$G$7*100 -> 112.20066 | I14: =$C14*$H$18/$H14 -> 2.1642112e+08
B15: =B14+1 -> 2024 | C15: 1.8554056e+08 | E15: 141567.29 | G15: =$C15/$E15 -> 1310.6175 | H15: =$G15/$G$7*100 -> 114.44467 | I15: =$C15*$H$18/$H15 -> 2.1858534e+08
B16: =B15+1 -> 2025 | C16: 1.930364e+08 | E16: 144398.63 | G16: =$C16/$E16 -> 1336.8298 | H16: =$G16/$G$7*100 -> 116.73356 | I16: =$C16*$H$18/$H16 -> 2.2295704e+08
B17: =B16+1 -> 2026 | C17: 2.1446344e+08 | D17: Estimate | E17: 145842.62 | F17: Estimate | G17: =$C17/$E17 -> 1470.5128 | H17: =$G17/$G$7*100 -> 128.40692 | I17: =$C17*$H$18/$H17 -> 2.2518661e+08
B18: =B17+1 -> 2027 | C18: 2.2969034e+08 | D18: Estimate | E18: 148759.47 | F18: Estimate | G18: =$C18/$E18 -> 1544.0384 | H18: =$G18/$G$7*100 -> 134.82727 | I18: =$C18*$H$18/$H18 -> 2.2969034e+08
B23: Layer1 | C23: 6000000 | D23: XS | E23: 4000000
B24: Layer2 | C24: 20000000 | D24: XS | E24: 10000000
A26: Step 2:claims index
B28: Inflation + superimposed inflation
F29: SI
F30: 0.015
E31: Source : Statbel & Plan Bureau | H31: Stabel | I31: Historical CPI
B32: Accident year | C32: Claims Index | E32: CPI | F32: CPI+ SI | H32: Plan Bureau | I32: CPI forecast
B33: 2016 | C33: 100 | E33: 0.019736101 | F33: =$E33+$F$30 -> 0.034736101
B34: 2017 | C34: =$C33*(1+$F34) -> 103.62786 | E34: 0.02127859 | F34: =$E34+$F$30 -> 0.03627859
B35: 2018 | C35: =$C34*(1+$F35) -> 107.30875 | E35: 0.020520277 | F35: =$E35+$F$30 -> 0.035520277
B36: 2019 | C36: =$C35*(1+$F36) -> 110.46523 | E36: 0.014414897 | F36: =$E36+$F$30 -> 0.029414897
B37: 2020 | C37: =$C36*(1+$F37) -> 112.94114 | E37: 0.0074135669 | F37: =$E37+$F$30 -> 0.022413567
B38: =2021 -> 2021 | C38: =$C37*(1+$F38) -> 117.39198 | E38: 0.024408451 | F38: =$E38+$F$30 -> 0.039408451
B39: =B38+1 -> 2022 | C39: =$C38*(1+$F39) -> 130.39822 | E39: 0.09579327 | F39: =$E39+$F$30 -> 0.11079327
B40: =B39+1 -> 2023 | C40: =$C39*(1+$F40) -> 137.71902 | E40: 0.041141822 | F40: =$E40+$F$30 -> 0.056141822
B41: =B40+1 -> 2024 | C41: =$C40*(1+$F41) -> 144.11485 | E41: 0.031441217 | F41: =$E41+$F$30 -> 0.046441217
B42: =B41+1 -> 2025 | C42: =$C41*(1+$F42) -> 149.83756 | E42: 0.024709355 | F42: =$E42+$F$30 -> 0.039709355
B43: =B42+1 -> 2026 | C43: =$C42*(1+$F43) -> 155.15598 | E43: 0.020494583 | F43: =$E43+$F$30 -> 0.035494583
B44: =B43+1 -> 2027 | C44: =$C43*(1+$F44) -> 160.58644 | E44: 0.02 | F44: =E44+$F$30 -> 0.035
B45: =B44+1 -> 2028 | C45: =$C44*(1+$F45) -> 165.8858 | E45: 0.018 | F45: =E45+$F$30 -> 0.033
B46: =B45+1 -> 2029 | C46: =$C45*(1+$F46) -> 171.36003 | E46: 0.018 | F46: =E46+$F$30 -> 0.033
B47: =B46+1 -> 2030 | C47: =$C46*(1+$F47) -> 177.01491 | E47: 0.018 | F47: =E47+$F$30 -> 0.033
B48: =B47+1 -> 2031 | C48: =$C47*(1+$F48) -> 182.8564 | E48: 0.018 | F48: =E48+$F$30 -> 0.033
B49: =B48+1 -> 2032 | C49: =$C48*(1+$F49) -> 188.89066 | E49: 0.018 | F49: =E49+$F$30 -> 0.033
...

Sheet Cum. payments
A1: 42374 | B1: 1075.2577 | C1: 178338.24 | D1: 178725.72 | E1: 193644.1 | F1: 407131.62 | G1: 407204.68 | H1: 446327.88 | I1: 450203.64 | J1: 464546.44 | K1: 464581.88 | N1: Paiement incremental | P1: 1 | Q1: 2 | R1: 3 | S1: 4 | T1: 5 | U1: 6 | V1: 7 | W1: 8 | X1: 9 | Y1: 10 | AA1: Indexed Incremental | AC1: 1 | AD1: 2 | AE1: 3 | AF1: 4 | AG1: 5 | AH1: 6 | AI1: 7 | AJ1: 8 | AK1: 9 | AL1: 10 | AY1: Origine | AZ1: 1 | BA1: 2 | BB1: 3 | BC1: 4 | BD1: 5 | BE1: 6 | BF1: 7 | BG1: 8 | BH1: 9 | BI1: 10 | BN1: Destination | BO1: 1 | BP1: 2 | BQ1: 3 | BR1: 4 | BS1: 5 | BT1: 6 | BU1: 7 | BV1: 8 | BW1: 9 | BX1: 10
A2: 42415 | B2: 133391.11 | C2: 254564.44 | D2: 511692.04 | E2: 809383.33 | F2: 1017876.8 | G2: 1018292.4 | H2: 1059163.7 | I2: 1073359.4 | J2: 1073779.3 | K2: 1073830.1 | O2: =YEAR($A1) -> 2016 | P2: =$B1 -> 1075.2577 | Q2: =C1-B1 -> 177262.98 | R2: =D1-C1 -> 387.48247 | S2: =E1-D1 -> 14918.38 | T2: =F1-E1 -> 213487.52 | U2: =G1-F1 -> 73.059712 | V2: =H1-G1 -> 39123.201 | W2: =I1-H1 -> 3875.7651 | X2: =J1-I1 -> 14342.796 | Y2: =K1-J1 -> 35.44499 | AA2: =P2*(Exposure!C44/Exposure!C33) -> 1726.7181 | AB2: =$O2 -> 2016 | AC2: =AA2 -> 1726.7181 | AD2: =Q2*VLOOKUP(BP2,Exposure!$B$33:$C$53,2,FALSE)/VLOOKUP(BA2,Exposure!$B$33:$C$53,2,FALSE) -> 283759.71 | AE2: =R2*VLOOKUP(BQ2,Exposure!$B$33:$C$53,2,FALSE)/VLOOKUP(BB2,Exposure!$B$33:$C$53,2,FALSE) -> 618.76602 | AF2: =S2*VLOOKUP(BR2,Exposure!$B$33:$C$53,2,FALSE)/VLOOKUP(BC2,Exposure!$B$33:$C$53,2,FALSE) -> 23905.946 | AG2: =T2*VLOOKUP(BS2,Exposure!$B$33:$C$53,2,FALSE)/VLOOKUP(BD2,Exposure!$B$33:$C$53,2,FALSE) -> 345645.15 | AH2: =U2*VLOOKUP(BT2,Exposure!$B$33:$C$53,2,FALSE)/VLOOKUP(BE2,Exposure!$B$33:$C$53,2,FALSE) -> 117.55741 | AI2: =V2*VLOOKUP(BU2,Exposure!$B$33:$C$53,2,FALSE)/VLOOKUP(BF2,Exposure!$B$33:$C$53,2,FALSE) -> 58542.804 | AJ2: =W2*VLOOKUP(BV2,Exposure!$B$33:$C$53,2,FALSE)/VLOOKUP(BG2,Exposure!$B$33:$C$53,2,FALSE) -> 5672.5021 | AK2: =X2*VLOOKUP(BW2,Exposure!$B$33:$C$53,2,FALSE)/VLOOKUP(BH2,Exposure!$B$33:$C$53,2,FALSE) -> 20722.232 | AL2: =Y2*VLOOKUP(BX2,Exposure!$B$33:$C$53,2,FALSE)/VLOOKUP(BI2,Exposure!$B$33:$C$53,2,FALSE) -> 50.879863 | AZ2: =$O2 -> 2016 | BA2: =$AZ2+BA$1-1 -> 2017 | BB2: =$AZ2+BB$1-1 -> 2018 | BC2: =$AZ2+BC$1-1 -> 2019 | BD2: =$AZ2+BD$1-1 -> 2020 | BE2: =$AZ2+BE$1-1 -> 2021 | BF2: =$AZ2+BF$1-1 -> 2022 | BG2: =$AZ2+BG$1-1 -> 2023 | BH2: =$AZ2+BH$1-1 -> 2024 | BI2: =$AZ2+BI$1-1 -> 2025 | BO2: 2027 | BP2: =$BO2+BP$1-1 -> 2028 | BQ2: =$BO2+BQ$1-1 -> 2029 | BR2: =$BO2+BR$1-1 -> 2030 | BS2: =$BO2+BS$1-1 -> 2031 | BT2: =$BO2+BT$1-1 -> 2032 | BU2: =$BO2+BU$1-1 -> 2033 | BV2: =$BO2+BV$1-1 -> 2034 | BW2: =$BO2+BW$1-1 -> 2035 | BX2: =$BO2+BX$1-1 -> 2036
A3: 42427 | B3: 895.77971 | C3: 22122.991 | D3: 44450.822 | E3: 539532.64 | F3: 548998.53 | G3: 553903.94 | H3: 553908.13 | I3: 564465.28 | J3: 571130.48 | K3: 574135.6 | O3: =YEAR($A2) -> 2016 | P3: =$B2 -> 133391.11 | Q3: =C2-B2 -> 121173.34 | R3: =D2-C2 -> 257127.6 | S3: =E2-D2 -> 297691.28 | T3: =F2-E2 -> 208493.43 | U3: =G2-F2 -> 415.66153 | V3: =H2-G2 -> 40871.32 | W3: =I2-H2 -> 14195.682 | X3: =J2-I2 -> 419.83501 | Y3: =K2-J2 -> 50.812493 | AB3: =$O3 -> 2016 | AC3: =P3*VLOOKUP(BO3,Exposure!$B$33:$C$53,2,FALSE)/VLOOKUP(AZ3,Exposure!$B$33:$C$53,2,FALSE) -> 214208.04 | AD3: =Q3*VLOOKUP(BP3,Exposure!$B$33:$C$53,2,FALSE)/VLOOKUP(BA3,Exposure!$B$33:$C$53,2,FALSE) -> 193972.31 | AE3: =R3*VLOOKUP(BQ3,Exposure!$B$33:$C$53,2,FALSE)/VLOOKUP(BB3,Exposure!$B$33:$C$53,2,FALSE) -> 410603.92 | AF3: =S3*VLOOKUP(BR3,Exposure!$B$33:$C$53,2,FALSE)/VLOOKUP(BC3,Exposure!$B$33:$C$53,2,FALSE) -> 477035.15 | AG3: =T3*VLOOKUP(BS3,Exposure!$B$33:$C$53,2,FALSE)/VLOOKUP(BD3,Exposure!$B$33:$C$53,2,FALSE) -> 337559.52 | AH3: =U3*VLOOKUP(BT3,Exposure!$B$33:$C$53,2,FALSE)/VLOOKUP(BE3,Exposure!$B$33:$C$53,2,FALSE) -> 668.82407 | AI3: =V3*VLOOKUP(BU3,Exposure!$B$33:$C$53,2,FALSE)/VLOOKUP(BF3,Exposure!$B$33:$C$53,2,FALSE) -> 61158.637 | AJ3: =W3*VLOOKUP(BV3,Exposure!$B$33:$C$53,2,FALSE)/VLOOKUP(BG3,Exposure!$B$33:$C$53,2,FALSE) -> 20776.553 | ... AL3: =Y3*VLOOKUP(BX3,Exposure!$B$33:$C$53,2,FALSE)/VLOOKUP(BI3,Exposure!$B$33:$C$53,2,FALSE) -> 72.939298 | AZ3: =$O3 -> 2016 | BA3: =$AZ3+BA$1-1 -> 2017 | BB3: =$AZ3+BB$1-1 -> 2018 | BC3: =$AZ3+BC$1-1 -> 2019 | BD3: =$AZ3+BD$1-1 -> 2020 | BE3: =$AZ3+BE$1-1 -> 2021 | BF3: =$AZ3+BF$1-1 -> 2022 | BG3: =$AZ3+BG$1-1 -> 2023 | BH3: =$AZ3+BH$1-1 -> 2024 | BI3: =$AZ3+BI$1-1 -> 2025 | BO3: 2027 | BP3: =$BO3+BP$1-1 -> 2028 | BQ3: =$BO3+BQ$1-1 -> 2029 | BR3: =$BO3+BR$1-1 -> 2030 | BS3: =$BO3+BS$1-1 -> 2031 | BT3: =$BO3+BT$1-1 -> 2032 | BU3: =$BO3+BU$1-1 -> 2033 | BV3: =$BO3+BV$1-1 -> 2034 | BW3: =$BO3+BW$1-1 -> 2035 | BX3: =$BO3+BX$1-1 -> 2036
A4: 42443 | B4: 39582.689 | C4: 807040.04 | D4: 2147508.1 | E4: 2306274.5 | F4: 2366505.9 | G4: 2505548.1 | H4: 2537192.5 | I4: 2539172.9 | J4: 2658962.7 | K4: 2663885.8 | O4: =YEAR($A3) -> 2016 | P4: =$B3 -> 895.77971 | Q4: =C3-B3 -> 21227.211 | R4: =D3-C3 -> 22327.832 | S4: =E3-D3 -> 495081.81 | T4: =F3-E3 -> 9465.8963 | U4: =G3-F3 -> 4905.4035 | V4: =H3-G3 -> 4.1962054 | W4: =I3-H3 -> 10557.146 | X4: =J3-I3 -> 6665.2014 | Y4: =K3-J3 -> 3005.1193 | AB4: =$O4 -> 2016 | AC4: =P4*VLOOKUP(BO4,Exposure!$B$33:$C$53,2,FALSE)/VLOOKUP(AZ4,Exposure!$B$33:$C$53,2,FALSE) -> 1438.5008 | AD4: =Q4*VLOOKUP(BP4,Exposure!$B$33:$C$53,2,FALSE)/VLOOKUP(BA4,Exposure!$B$33:$C$53,2,FALSE) -> 33980.175 | AE4: =R4*VLOOKUP(BQ4,Exposure!$B$33:$C$53,2,FALSE)/VLOOKUP(BB4,Exposure!$B$33:$C$53,2,FALSE) -> 35655.041 | AF4: =S4*VLOOKUP(BR4,Exposure!$B$33:$C$53,2,FALSE)/VLOOKUP(BC4,Exposure!$B$33:$C$53,2,FALSE) -> 793343.44 | AG4: =T4*VLOOKUP(BS4,Exposure!$B$33:$C$53,2,FALSE)/VLOOKUP(BD4,Exposure!$B$33:$C$53,2,FALSE) -> 15325.679 | AH4: =U4*VLOOKUP(BT4,Exposure!$B$33:$C$53,2,FALSE)/VLOOKUP(BE4,Exposure!$B$33:$C$53,2,FALSE) -> 7893.0852 | AI4: =V4*VLOOKUP(BU4,Exposure!$B$33:$C$53,2,FALSE)/VLOOKUP(BF4,Exposure!$B$33:$C$53,2,FALSE) -> 6.2790781 | AJ4: =W4*VLOOKUP(BV4,Exposure!$B$33:$C$53,2,FALSE)/VLOOKUP(BG4,Exposure!$B$33:$C$53,2,FALSE) -> 15451.254 | ... AL4: =Y4*VLOOKUP(BX4,Exposure!$B$33:$C$53,2,FALSE)/VLOOKUP(BI4,Exposure!$B$33:$C$53,2,FALSE) -> 4313.7283 | AZ4: =$O4 -> 2016 | BA4: =$AZ4+BA$1-1 -> 2017 | BB4: =$AZ4+BB$1-1 -> 2018 | BC4: =$AZ4+BC$1-1 -> 2019 | BD4: =$AZ4+BD$1-1 -> 2020 | BE4: =$AZ4+BE$1-1 -> 2021 | BF4: =$AZ4+BF$1-1 -> 2022 | BG4: =$AZ4+BG$1-1 -> 2023 | BH4: =$AZ4+BH$1-1 -> 2024 | BI4: =$AZ4+BI$1-1 -> 2025 | BO4: 2027 | BP4: =$BO4+BP$1-1 -> 2028 | BQ4: =$BO4+BQ$1-1 -> 2029 | BR4: =$BO4+BR$1-1 -> 2030 | BS4: =$BO4+BS$1-1 -> 2031 | BT4: =$BO4+BT$1-1 -> 2032 | BU4: =$BO4+BU$1-1 -> 2033 | BV4: =$BO4+BV$1-1 -> 2034 | BW4: =$BO4+BW$1-1 -> 2035 | BX4: =$BO4+BX$1-1 -> 2036
A5: 42500 | B5: 31450.465 | C5: 44049.75 | D5: 408949.07 | E5: 414693.51 | F5: 428592.54 | G5: 942353.73 | H5: 949031.56 | I5: 949377.72 | J5: 950321.2 | K5: 952171.9 | O5: =YEAR($A4) -> 2016 | P5: =$B4 -> 39582.689 | Q5: =C4-B4 -> 767457.36 | R5: =D4-C4 -> 1340468 | S5: =E4-D4 -> 158766.46 | T5: =F4-E4 -> 60231.336 | U5: =G4-F4 -> 139042.21 | V5: =H4-G4 -> 31644.399 | W5: =I4-H4 -> 1980.4173 | X5: =J4-I4 -> 119789.84 | Y5: =K4-J4 -> 4923.0747 | AB5: =$O5 -> 2016 | AC5: =P5*VLOOKUP(BO5,Exposure!$B$33:$C$53,2,FALSE)/VLOOKUP(AZ5,Exposure!$B$33:$C$53,2,FALSE) -> 63564.432 | AD5: =Q5*VLOOKUP(BP5,Exposure!$B$33:$C$53,2,FALSE)/VLOOKUP(BA5,Exposure!$B$33:$C$53,2,FALSE) -> 1228533.3 | AE5: =R5*VLOOKUP(BQ5,Exposure!$B$33:$C$53,2,FALSE)/VLOOKUP(BB5,Exposure!$B$33:$C$53,2,FALSE) -> 2140577 | AF5: =S5*VLOOKUP(BR5,Exposure!$B$33:$C$53,2,FALSE)/VLOOKUP(BC5,Exposure!$B$33:$C$53,2,FALSE) -> 254415.18 | AG5: =T5*VLOOKUP(BS5,Exposure!$B$33:$C$53,2,FALSE)/VLOOKUP(BD5,Exposure!$B$33:$C$53,2,FALSE) -> 97517.033 | AH5: =U5*VLOOKUP(BT5,Exposure!$B$33:$C$53,2,FALSE)/VLOOKUP(BE5,Exposure!$B$33:$C$53,2,FALSE) -> 223727.16 | AI5: =V5*VLOOKUP(BU5,Exposure!$B$33:$C$53,2,FALSE)/VLOOKUP(BF5,Exposure!$B$33:$C$53,2,FALSE) -> 47351.745 | AJ5: =W5*VLOOKUP(BV5,Exposure!$B$33:$C$53,2,FALSE)/VLOOKUP(BG5,Exposure!$B$33:$C$53,2,FALSE) -> 2898.5042 | ... AL5: =Y5*VLOOKUP(BX5,Exposure!$B$33:$C$53,2,FALSE)/VLOOKUP(BI5,Exposure!$B$33:$C$53,2,FALSE) -> 7066.8765 | AZ5: =$O5 -> 2016 | BA5: =$AZ5+BA$1-1 -> 2017 | BB5: =$AZ5+BB$1-1 -> 2018 | BC5: =$AZ5+BC$1-1 -> 2019 | BD5: =$AZ5+BD$1-1 -> 2020 | BE5: =$AZ5+BE$1-1 -> 2021 | BF5: =$AZ5+BF$1-1 -> 2022 | BG5: =$AZ5+BG$1-1 -> 2023 | BH5: =$AZ5+BH$1-1 -> 2024 | BI5: =$AZ5+BI$1-1 -> 2025 | BO5: 2027 | BP5: =$BO5+BP$1-1 -> 2028 | BQ5: =$BO5+BQ$1-1 -> 2029 | BR5: =$BO5+BR$1-1 -> 2030 | BS5: =$BO5+BS$1-1 -> 2031 | BT5: =$BO5+BT$1-1 -> 2032 | BU5: =$BO5+BU$1-1 -> 2033 | BV5: =$BO5+BV$1-1 -> 2034 | BW5: =$BO5+BW$1-1 -> 2035 | BX5: =$BO5+BX$1-1 -> 2036
A6: 42513 | B6: 227513.45 | C6: 328297.69 | D6: 351684.06 | E6: 521237.26 | F6: 1849971.6 | G6: 1876628.4 | H6: 1877682.2 | I6: 1877698.8 | J6: 1877715.1 | K6: 1877715.1 | O6: =YEAR($A5) -> 2016 | P6: =$B5 -> 31450.465 | Q6: =C5-B5 -> 12599.285 | R6: =D5-C5 -> 364899.32 | S6: =E5-D5 -> 5744.4408 | T6: =F5-E5 -> 13899.022 | U6: =G5-F5 -> 513761.19 | V6: =H5-G5 -> 6677.8279 | W6: =I5-H5 -> 346.16058 | X6: =J5-I5 -> 943.48209 | Y6: =K5-J5 -> 1850.7003 | AB6: =$O6 -> 2016 | AC6: =P6*VLOOKUP(BO6,Exposure!$B$33:$C$53,2,FALSE)/VLOOKUP(AZ6,Exposure!$B$33:$C$53,2,FALSE) -> 50505.183 | AD6: =Q6*VLOOKUP(BP6,Exposure!$B$33:$C$53,2,FALSE)/VLOOKUP(BA6,Exposure!$B$33:$C$53,2,FALSE) -> 20168.731 | AE6: =R6*VLOOKUP(BQ6,Exposure!$B$33:$C$53,2,FALSE)/VLOOKUP(BB6,Exposure!$B$33:$C$53,2,FALSE) -> 582703.26 | AF6: =S6*VLOOKUP(BR6,Exposure!$B$33:$C$53,2,FALSE)/VLOOKUP(BC6,Exposure!$B$33:$C$53,2,FALSE) -> 9205.1743 | AG6: =T6*VLOOKUP(BS6,Exposure!$B$33:$C$53,2,FALSE)/VLOOKUP(BD6,Exposure!$B$33:$C$53,2,FALSE) -> 22503.094 | AH6: =U6*VLOOKUP(BT6,Exposure!$B$33:$C$53,2,FALSE)/VLOOKUP(BE6,Exposure!$B$33:$C$53,2,FALSE) -> 826672.24 | AI6: =V6*VLOOKUP(BU6,Exposure!$B$33:$C$53,2,FALSE)/VLOOKUP(BF6,Exposure!$B$33:$C$53,2,FALSE) -> 9992.5048 | AJ6: =W6*VLOOKUP(BV6,Exposure!$B$33:$C$53,2,FALSE)/VLOOKUP(BG6,Exposure!$B$33:$C$53,2,FALSE) -> 506.63458 | ... AL6: =Y6*VLOOKUP(BX6,Exposure!$B$33:$C$53,2,FALSE)/VLOOKUP(BI6,Exposure!$B$33:$C$53,2,FALSE) -> 2656.6061 | AZ6: =$O6 -> 2016 | BA6: =$AZ6+BA$1-1 -> 2017 | BB6: =$AZ6+BB$1-1 -> 2018 | BC6: =$AZ6+BC$1-1 -> 2019 | BD6: =$AZ6+BD$1-1 -> 2020 | BE6: =$AZ6+BE$1-1 -> 2021 | BF6: =$AZ6+BF$1-1 -> 2022 | BG6: =$AZ6+BG$1-1 -> 2023 | BH6: =$AZ6+BH$1-1 -> 2024 | BI6: =$AZ6+BI$1-1 -> 2025 | BO6: 2027 | BP6: =$BO6+BP$1-1 -> 2028 | BQ6: =$BO6+BQ$1-1 -> 2029 | BR6: =$BO6+BR$1-1 -> 2030 | BS6: =$BO6+BS$1-1 -> 2031 | BT6: =$BO6+BT$1-1 -> 2032 | BU6: =$BO6+BU$1-1 -> 2033 | BV6: =$BO6+BV$1-1 -> 2034 | BW6: =$BO6+BW$1-1 -> 2035 | BX6: =$BO6+BX$1-1 -> 2036
A7: 42516 | B7: 162919.32 | C7: 4294009.9 | D7: 4413502.1 | E7: 6709541.2 | F7: 6886454.5 | G7: 7344043.1 | H7: 8021732.7 | I7: 8035665.5 | J7: 8044842.8 | K7: 8049749.9 | O7: =YEAR($A6) -> 2016 | P7: =$B6 -> 227513.45 | Q7: =C6-B6 -> 100784.24 | R7: =D6-C6 -> 23386.368 | S7: =E6-D6 -> 169553.2 | T7: =F6-E6 -> 1328734.3 | U7: =G6-F6 -> 26656.775 | V7: =H6-G6 -> 1053.8106 | W7: =I6-H6 -> 16.613752 | X7: =J6-I6 -> 16.280591 | Y7: =K6-J6 -> 0.04388575 | AB7: =$O7 -> 2016 | AC7: =P7*VLOOKUP(BO7,Exposure!$B$33:$C$53,2,FALSE)/VLOOKUP(AZ7,Exposure!$B$33:$C$53,2,FALSE) -> 365355.76 | AD7: =Q7*VLOOKUP(BP7,Exposure!$B$33:$C$53,2,FALSE)/VLOOKUP(BA7,Exposure!$B$33:$C$53,2,FALSE) -> 161333.78 | AE7: =R7*VLOOKUP(BQ7,Exposure!$B$33:$C$53,2,FALSE)/VLOOKUP(BB7,Exposure!$B$33:$C$53,2,FALSE) -> 37345.405 | AF7: =S7*VLOOKUP(BR7,Exposure!$B$33:$C$53,2,FALSE)/VLOOKUP(BC7,Exposure!$B$33:$C$53,2,FALSE) -> 271700.38 | AG7: =T7*VLOOKUP(BS7,Exposure!$B$33:$C$53,2,FALSE)/VLOOKUP(BD7,Exposure!$B$33:$C$53,2,FALSE) -> 2151276 | AH7: =U7*VLOOKUP(BT7,Exposure!$B$33:$C$53,2,FALSE)/VLOOKUP(BE7,Exposure!$B$33:$C$53,2,FALSE) -> 42892.333 | AI7: =V7*VLOOKUP(BU7,Exposure!$B$33:$C$53,2,FALSE)/VLOOKUP(BF7,Exposure!$B$33:$C$53,2,FALSE) -> 1576.8912 | AJ7: =W7*VLOOKUP(BV7,Exposure!$B$33:$C$53,2,FALSE)/VLOOKUP(BG7,Exposure!$B$33:$C$53,2,FALSE) -> 24.315598 | ... AL7: =Y7*VLOOKUP(BX7,Exposure!$B$33:$C$53,2,FALSE)/VLOOKUP(BI7,Exposure!$B$33:$C$53,2,FALSE) -> 0.062996235 | AZ7: =$O7 -> 2016 | BA7: =$AZ7+BA$1-1 -> 2017 | BB7: =$AZ7+BB$1-1 -> 2018 | BC7: =$AZ7+BC$1-1 -> 2019 | BD7: =$AZ7+BD$1-1 -> 2020 | BE7: =$AZ7+BE$1-1 -> 2021 | BF7: =$AZ7+BF$1-1 -> 2022 | BG7: =$AZ7+BG$1-1 -> 2023 | BH7: =$AZ7+BH$1-1 -> 2024 | BI7: =$AZ7+BI$1-1 -> 2025 | BO7: 2027 | BP7: =$BO7+BP$1-1 -> 2028 | BQ7: =$BO7+BQ$1-1 -> 2029 | BR7: =$BO7+BR$1-1 -> 2030 | BS7: =$BO7+BS$1-1 -> 2031 | BT7: =$BO7+BT$1-1 -> 2032 | BU7: =$BO7+BU$1-1 -> 2033 | BV7: =$BO7+BV$1-1 -> 2034 | BW7: =$BO7+BW$1-1 -> 2035 | BX7: =$BO7+BX$1-1 -> 2036
A8: 42539 | B8: 190882.51 | C8: 606855.1 | D8: 634156.62 | E8: 638305.45 | F8: 689075.99 | G8: 731494.3 | H8: 732498.61 | I8: 735429.09 | J8: 735871.91 | K8: 795241.18 | O8: =YEAR($A7) -> 2016 | P8: =$B7 -> 162919.32 | Q8: =C7-B7 -> 4131090.6 | R8: =D7-C7 -> 119492.18 | S8: =E7-D7 -> 2296039.1 | T8: =F7-E7 -> 176913.34 | U8: =G7-F7 -> 457588.54 | V8: =H7-G7 -> 677689.66 | W8: =I7-H7 -> 13932.768 | X8: =J7-I7 -> 9177.3157 | Y8: =K7-J7 -> 4907.1342 | AB8: =$O8 -> 2016 | AC8: =P8*VLOOKUP(BO8,Exposure!$B$33:$C$53,2,FALSE)/VLOOKUP(AZ8,Exposure!$B$33:$C$53,2,FALSE) -> 261626.35 | AD8: =Q8*VLOOKUP(BP8,Exposure!$B$33:$C$53,2,FALSE)/VLOOKUP(BA8,Exposure!$B$33:$C$53,2,FALSE) -> 6612982.8 | AE8: =R8*VLOOKUP(BQ8,Exposure!$B$33:$C$53,2,FALSE)/VLOOKUP(BB8,Exposure!$B$33:$C$53,2,FALSE) -> 190815.61 | AF8: =S8*VLOOKUP(BR8,Exposure!$B$33:$C$53,2,FALSE)/VLOOKUP(BC8,Exposure!$B$33:$C$53,2,FALSE) -> 3679285.9 | AG8: =T8*VLOOKUP(BS8,Exposure!$B$33:$C$53,2,FALSE)/VLOOKUP(BD8,Exposure!$B$33:$C$53,2,FALSE) -> 286430.04 | AH8: =U8*VLOOKUP(BT8,Exposure!$B$33:$C$53,2,FALSE)/VLOOKUP(BE8,Exposure!$B$33:$C$53,2,FALSE) -> 736287.11 | AI8: =V8*VLOOKUP(BU8,Exposure!$B$33:$C$53,2,FALSE)/VLOOKUP(BF8,Exposure!$B$33:$C$53,2,FALSE) -> 1014074.8 | AJ8: =W8*VLOOKUP(BV8,Exposure!$B$33:$C$53,2,FALSE)/VLOOKUP(BG8,Exposure!$B$33:$C$53,2,FALSE) -> 20391.756 | ... AL8: =Y8*VLOOKUP(BX8,Exposure!$B$33:$C$53,2,FALSE)/VLOOKUP(BI8,Exposure!$B$33:$C$53,2,FALSE) -> 7043.9946 | AZ8: =$O8 -> 2016 | BA8: =$AZ8+BA$1-1 -> 2017 | BB8: =$AZ8+BB$1-1 -> 2018 | BC8: =$AZ8+BC$1-1 -> 2019 | BD8: =$AZ8+BD$1-1 -> 2020 | BE8: =$AZ8+BE$1-1 -> 2021 | BF8: =$AZ8+BF$1-1 -> 2022 | BG8: =$AZ8+BG$1-1 -> 2023 | BH8: =$AZ8+BH$1-1 -> 2024 | BI8: =$AZ8+BI$1-1 -> 2025 | BO8: 2027 | BP8: =$BO8+BP$1-1 -> 2028 | BQ8: =$BO8+BQ$1-1 -> 2029 | BR8: =$BO8+BR$1-1 -> 2030 | BS8: =$BO8+BS$1-1 -> 2031 | BT8: =$BO8+BT$1-1 -> 2032 | BU8: =$BO8+BU$1-1 -> 2033 | BV8: =$BO8+BV$1-1 -> 2034 | BW8: =$BO8+BW$1-1 -> 2035 | BX8: =$BO8+BX$1-1 -> 2036
A9: 42562 | B9: 704.26176 | C9: 216262.11 | D9: 247957.86 | E9: 413708.58 | F9: 598681.15 | G9: 598688.61 | H9: 601319.53 | I9: 601779.27 | J9: 601801.63 | K9: 601802.77 | O9: =YEAR($A8) -> 2016 | P9: =$B8 -> 190882.51 | Q9: =C8-B8 -> 415972.59 | R9: =D8-C8 -> 27301.522 | S9: =E8-D8 -> 4148.8235 | T9: =F8-E8 -> 50770.547 | U9: =G8-F8 -> 42418.302 | V9: =H8-G8 -> 1004.3159 | W9: =I8-H8 -> 2930.4739 | X9: =J8-I8 -> 442.82599 | Y9: =K8-J8 -> 59369.264 | AB9: =$O9 -> 2016 | AC9: =P9*VLOOKUP(BO9,Exposure!$B$33:$C$53,2,FALSE)/VLOOKUP(AZ9,Exposure!$B$33:$C$53,2,FALSE) -> 306531.43 | AD9: =Q9*VLOOKUP(BP9,Exposure!$B$33:$C$53,2,FALSE)/VLOOKUP(BA9,Exposure!$B$33:$C$53,2,FALSE) -> 665882.18 | AE9: =R9*VLOOKUP(BQ9,Exposure!$B$33:$C$53,2,FALSE)/VLOOKUP(BB9,Exposure!$B$33:$C$53,2,FALSE) -> 43597.467 | AF9: =S9*VLOOKUP(BR9,Exposure!$B$33:$C$53,2,FALSE)/VLOOKUP(BC9,Exposure!$B$33:$C$53,2,FALSE) -> 6648.2787 | AG9: =T9*VLOOKUP(BS9,Exposure!$B$33:$C$53,2,FALSE)/VLOOKUP(BD9,Exposure!$B$33:$C$53,2,FALSE) -> 82199.622 | AH9: =U9*VLOOKUP(BT9,Exposure!$B$33:$C$53,2,FALSE)/VLOOKUP(BE9,Exposure!$B$33:$C$53,2,FALSE) -> 68253.565 | AI9: =V9*VLOOKUP(BU9,Exposure!$B$33:$C$53,2,FALSE)/VLOOKUP(BF9,Exposure!$B$33:$C$53,2,FALSE) -> 1502.8287 | AJ9: =W9*VLOOKUP(BV9,Exposure!$B$33:$C$53,2,FALSE)/VLOOKUP(BG9,Exposure!$B$33:$C$53,2,FALSE) -> 4288.9905 | ... AL9: =Y9*VLOOKUP(BX9,Exposure!$B$33:$C$53,2,FALSE)/VLOOKUP(BI9,Exposure!$B$33:$C$53,2,FALSE) -> 85222.2 | AZ9: =$O9 -> 2016 | BA9: =$AZ9+BA$1-1 -> 2017 | BB9: =$AZ9+BB$1-1 -> 2018 | BC9: =$AZ9+BC$1-1 -> 2019 | BD9: =$AZ9+BD$1-1 -> 2020 | BE9: =$AZ9+BE$1-1 -> 2021 | BF9: =$AZ9+BF$1-1 -> 2022 | BG9: =$AZ9+BG$1-1 -> 2023 | BH9: =$AZ9+BH$1-1 -> 2024 | BI9: =$AZ9+BI$1-1 -> 2025 | BO9: 2027 | BP9: =$BO9+BP$1-1 -> 2028 | BQ9: =$BO9+BQ$1-1 -> 2029 | BR9: =$BO9+BR$1-1 -> 2030 | BS9: =$BO9+BS$1-1 -> 2031 | BT9: =$BO9+BT$1-1 -> 2032 | BU9: =$BO9+BU$1-1 -> 2033 | BV9: =$BO9+BV$1-1 -> 2034 | BW9: =$BO9+BW$1-1 -> 2035 | BX9: =$BO9+BX$1-1 -> 2036
A10: 42598 | B10: 746652.24 | C10: 750549.29 | D10: 1150922.8 | E10: 1162892.8 | F10: 2120678 | G10: 2263720.7 | H10: 2281562.4 | I10: 2294593.8 | J10: 2296186.9 | K10: 2296192.7 | O10: =YEAR($A9) -> 2016 | P10: =$B9 -> 704.26176 | Q10: =C9-B9 -> 215557.85 | R10: =D9-C9 -> 31695.748 | S10: =E9-D9 -> 165750.72 | T10: =F9-E9 -> 184972.58 | U10: =G9-F9 -> 7.4575811 | V10: =H9-G9 -> 2630.9208 | W10: =I9-H9 -> 459.73944 | X10: =J9-I9 -> 22.356881 | Y10: =K9-J9 -> 1.1395802 | AB10: =$O10 -> 2016 | AC10: =P10*VLOOKUP(BO10,Exposure!$B$33:$C$53,2,FALSE)/VLOOKUP(AZ10,Exposure!$B$33:$C$53,2,FALSE) -> 1130.9489 | AD10: =Q10*VLOOKUP(BP10,Exposure!$B$33:$C$53,2,FALSE)/VLOOKUP(BA10,Exposure!$B$33:$C$53,2,FALSE) -> 345061.51 | AE10: =R10*VLOOKUP(BQ10,Exposure!$B$33:$C$53,2,FALSE)/VLOOKUP(BB10,Exposure!$B$33:$C$53,2,FALSE) -> 50614.551 | AF10: =S10*VLOOKUP(BR10,Exposure!$B$33:$C$53,2,FALSE)/VLOOKUP(BC10,Exposure!$B$33:$C$53,2,FALSE) -> 265607.1 | AG10: =T10*VLOOKUP(BS10,Exposure!$B$33:$C$53,2,FALSE)/VLOOKUP(BD10,Exposure!$B$33:$C$53,2,FALSE) -> 299478.28 | AH10: =U10*VLOOKUP(BT10,Exposure!$B$33:$C$53,2,FALSE)/VLOOKUP(BE10,Exposure!$B$33:$C$53,2,FALSE) -> 11.99969 | AI10: =V10*VLOOKUP(BU10,Exposure!$B$33:$C$53,2,FALSE)/VLOOKUP(BF10,Exposure!$B$33:$C$53,2,FALSE) -> 3936.8322 | AJ10: =W10*VLOOKUP(BV10,Exposure!$B$33:$C$53,2,FALSE)/VLOOKUP(BG10,Exposure!$B$33:$C$53,2,FALSE) -> 672.86662 | ... AL10: =Y10*VLOOKUP(BX10,Exposure!$B$33:$C$53,2,FALSE)/VLOOKUP(BI10,Exposure!$B$33:$C$53,2,FALSE) -> 1.6358217 | AZ10: =$O10 -> 2016 | BA10: =$AZ10+BA$1-1 -> 2017 | BB10: =$AZ10+BB$1-1 -> 2018 | BC10: =$AZ10+BC$1-1 -> 2019 | BD10: =$AZ10+BD$1-1 -> 2020 | BE10: =$AZ10+BE$1-1 -> 2021 | BF10: =$AZ10+BF$1-1 -> 2022 | BG10: =$AZ10+BG$1-1 -> 2023 | BH10: =$AZ10+BH$1-1 -> 2024 | BI10: =$AZ10+BI$1-1 -> 2025 | BO10: 2027 | BP10: =$BO10+BP$1-1 -> 2028 | BQ10: =$BO10+BQ$1-1 -> 2029 | BR10: =$BO10+BR$1-1 -> 2030 | BS10: =$BO10+BS$1-1 -> 2031 | BT10: =$BO10+BT$1-1 -> 2032 | BU10: =$BO10+BU$1-1 -> 2033 | BV10: =$BO10+BV$1-1 -> 2034 | BW10: =$BO10+BW$1-1 -> 2035 | BX10: =$BO10+BX$1-1 -> 2036
A11: 42618 | B11: 22115.283 | C11: 223882.25 | D11: 1902460.6 | E11: 1933629.7 | F11: 2145163.9 | G11: 2152022 | H11: 2161925.9 | I11: 2161925.9 | J11: 2162166.1 | K11: 2162166.9 | O11: =YEAR($A10) -> 2016 | P11: =$B10 -> 746652.24 | Q11: =C10-B10 -> 3897.0431 | R11: =D10-C10 -> 400373.52 | S11: =E10-D10 -> 11970.019 | T11: =F10-E10 -> 957785.16 | U11: =G10-F10 -> 143042.69 | V11: =H10-G10 -> 17841.754 | W11: =I10-H10 -> 13031.397 | X11: =J10-I10 -> 1593.089 | Y11: =K10-J10 -> 5.7913746 | AB11: =$O11 -> 2016 | AC11: =P11*VLOOKUP(BO11,Exposure!$B$33:$C$53,2,FALSE)/VLOOKUP(AZ11,Exposure!$B$33:$C$53,2,FALSE) -> 1199022.3 | AD11: =Q11*VLOOKUP(BP11,Exposure!$B$33:$C$53,2,FALSE)/VLOOKUP(BA11,Exposure!$B$33:$C$53,2,FALSE) -> 6238.3234 | AE11: =R11*VLOOKUP(BQ11,Exposure!$B$33:$C$53,2,FALSE)/VLOOKUP(BB11,Exposure!$B$33:$C$53,2,FALSE) -> 639351.58 | AF11: =S11*VLOOKUP(BR11,Exposure!$B$33:$C$53,2,FALSE)/VLOOKUP(BC11,Exposure!$B$33:$C$53,2,FALSE) -> 19181.347 | AG11: =T11*VLOOKUP(BS11,Exposure!$B$33:$C$53,2,FALSE)/VLOOKUP(BD11,Exposure!$B$33:$C$53,2,FALSE) -> 1550693.9 | AH11: =U11*VLOOKUP(BT11,Exposure!$B$33:$C$53,2,FALSE)/VLOOKUP(BE11,Exposure!$B$33:$C$53,2,FALSE) -> 230164.17 | AI11: =V11*VLOOKUP(BU11,Exposure!$B$33:$C$53,2,FALSE)/VLOOKUP(BF11,Exposure!$B$33:$C$53,2,FALSE) -> 26697.874 | AJ11: =W11*VLOOKUP(BV11,Exposure!$B$33:$C$53,2,FALSE)/VLOOKUP(BG11,Exposure!$B$33:$C$53,2,FALSE) -> 19072.526 | ... AL11: =Y11*VLOOKUP(BX11,Exposure!$B$33:$C$53,2,FALSE)/VLOOKUP(BI11,Exposure!$B$33:$C$53,2,FALSE) -> 8.3132863 | AZ11: =$O11 -> 2016 | BA11: =$AZ11+BA$1-1 -> 2017 | BB11: =$AZ11+BB$1-1 -> 2018 | BC11: =$AZ11+BC$1-1 -> 2019 | BD11: =$AZ11+BD$1-1 -> 2020 | BE11: =$AZ11+BE$1-1 -> 2021 | BF11: =$AZ11+BF$1-1 -> 2022 | BG11: =$AZ11+BG$1-1 -> 2023 | BH11: =$AZ11+BH$1-1 -> 2024 | BI11: =$AZ11+BI$1-1 -> 2025 | BO11: 2027 | BP11: =$BO11+BP$1-1 -> 2028 | BQ11: =$BO11+BQ$1-1 -> 2029 | BR11: =$BO11+BR$1-1 -> 2030 | BS11: =$BO11+BS$1-1 -> 2031 | BT11: =$BO11+BT$1-1 -> 2032 | BU11: =$BO11+BU$1-1 -> 2033 | BV11: =$BO11+BV$1-1 -> 2034 | BW11: =$BO11+BW$1-1 -> 2035 | BX11: =$BO11+BX$1-1 -> 2036
A12: 42630 | B12: 5220.8083 | C12: 359287.75 | D12: 369384.15 | E12: 1107719.6 | F12: 1168827.6 | G12: 1177317.7 | H12: 1177319.4 | I12: 1177320 | J12: 1177321.5 | K12: 1177322.1 | O12: =YEAR($A11) -> 2016 | P12: =$B11 -> 22115.283 | Q12: =C11-B11 -> 201766.97 | R12: =D11-C11 -> 1678578.4 | S12: =E11-D11 -> 31169.075 | T12: =F11-E11 -> 211534.19 | U12: =G11-F11 -> 6858.1199 | V12: =H11-G11 -> 9903.8586 | W12: =I11-H11 -> 0.063418521 | X12: =J11-I11 -> 240.17136 | Y12: =K11-J11 -> 0.80848745 | AB12: =$O12 -> 2016 | AC12: =P12*VLOOKUP(BO12,Exposure!$B$33:$C$53,2,FALSE)/VLOOKUP(AZ12,Exposure!$B$33:$C$53,2,FALSE) -> 35514.146 | AD12: =Q12*VLOOKUP(BP12,Exposure!$B$33:$C$53,2,FALSE)/VLOOKUP(BA12,Exposure!$B$33:$C$53,2,FALSE) -> 322985.29 | AE12: =R12*VLOOKUP(BQ12,Exposure!$B$33:$C$53,2,FALSE)/VLOOKUP(BB12,Exposure!$B$33:$C$53,2,FALSE) -> 2680501.3 | AF12: =S12*VLOOKUP(BR12,Exposure!$B$33:$C$53,2,FALSE)/VLOOKUP(BC12,Exposure!$B$33:$C$53,2,FALSE) -> 49946.858 | AG12: =T12*VLOOKUP(BS12,Exposure!$B$33:$C$53,2,FALSE)/VLOOKUP(BD12,Exposure!$B$33:$C$53,2,FALSE) -> 342482.63 | AH12: =U12*VLOOKUP(BT12,Exposure!$B$33:$C$53,2,FALSE)/VLOOKUP(BE12,Exposure!$B$33:$C$53,2,FALSE) -> 11035.122 | AI12: =V12*VLOOKUP(BU12,Exposure!$B$33:$C$53,2,FALSE)/VLOOKUP(BF12,Exposure!$B$33:$C$53,2,FALSE) -> 14819.842 | AJ12: =W12*VLOOKUP(BV12,Exposure!$B$33:$C$53,2,FALSE)/VLOOKUP(BG12,Exposure!$B$33:$C$53,2,FALSE) -> 0.09281824 | ... AL12: =Y12*VLOOKUP(BX12,Exposure!$B$33:$C$53,2,FALSE)/VLOOKUP(BI12,Exposure!$B$33:$C$53,2,FALSE) -> 1.1605513 | AZ12: =$O12 -> 2016 | BA12: =$AZ12+BA$1-1 -> 2017 | BB12: =$AZ12+BB$1-1 -> 2018 | BC12: =$AZ12+BC$1-1 -> 2019 | BD12: =$AZ12+BD$1-1 -> 2020 | BE12: =$AZ12+BE$1-1 -> 2021 | BF12: =$AZ12+BF$1-1 -> 2022 | BG12: =$AZ12+BG$1-1 -> 2023 | BH12: =$AZ12+BH$1-1 -> 2024 | BI12: =$AZ12+BI$1-1 -> 2025 | BO12: 2027 | BP12: =$BO12+BP$1-1 -> 2028 | BQ12: =$BO12+BQ$1-1 -> 2029 | BR12: =$BO12+BR$1-1 -> 2030 | BS12: =$BO12+BS$1-1 -> 2031 | BT12: =$BO12+BT$1-1 -> 2032 | BU12: =$BO12+BU$1-1 -> 2033 | BV12: =$BO12+BV$1-1 -> 2034 | BW12: =$BO12+BW$1-1 -> 2035 | BX12: =$BO12+BX$1-1 -> 2036
A13: 42673 | B13: 48508.148 | C13: 58558.077 | D13: 778959.71 | E13: 828568.29 | F13: 828631.11 | G13: 830826.09 | H13: 831209.69 | I13: 831230.88 | J13: 831251.15 | K13: 831284.8 | O13: =YEAR($A12) -> 2016 | P13: =$B12 -> 5220.8083 | Q13: =C12-B12 -> 354066.95 | R13: =D12-C12 -> 10096.399 | S13: =E12-D12 -> 738335.41 | T13: =F12-E12 -> 61108.085 | U13: =G12-F12 -> 8490.0964 | V13: =H12-G12 -> 1.6240313 | W13: =I12-H12 -> 0.58914969 | X13: =J12-I12 -> 1.5477351 | Y13: =K12-J12 -> 0.6051519 | AB13: =$O13 -> 2016 | AC13: =P13*VLOOKUP(BO13,Exposure!$B$33:$C$53,2,FALSE)/VLOOKUP(AZ13,Exposure!$B$33:$C$53,2,FALSE) -> 8383.9104 | AD13: =Q13*VLOOKUP(BP13,Exposure!$B$33:$C$53,2,FALSE)/VLOOKUP(BA13,Exposure!$B$33:$C$53,2,FALSE) -> 566784.62 | AE13: =R13*VLOOKUP(BQ13,Exposure!$B$33:$C$53,2,FALSE)/VLOOKUP(BB13,Exposure!$B$33:$C$53,2,FALSE) -> 16122.816 | AF13: =S13*VLOOKUP(BR13,Exposure!$B$33:$C$53,2,FALSE)/VLOOKUP(BC13,Exposure!$B$33:$C$53,2,FALSE) -> 1183145 | AG13: =T13*VLOOKUP(BS13,Exposure!$B$33:$C$53,2,FALSE)/VLOOKUP(BD13,Exposure!$B$33:$C$53,2,FALSE) -> 98936.525 | AH13: =U13*VLOOKUP(BT13,Exposure!$B$33:$C$53,2,FALSE)/VLOOKUP(BE13,Exposure!$B$33:$C$53,2,FALSE) -> 13661.069 | AI13: =V13*VLOOKUP(BU13,Exposure!$B$33:$C$53,2,FALSE)/VLOOKUP(BF13,Exposure!$B$33:$C$53,2,FALSE) -> 2.4301526 | AJ13: =W13*VLOOKUP(BV13,Exposure!$B$33:$C$53,2,FALSE)/VLOOKUP(BG13,Exposure!$B$33:$C$53,2,FALSE) -> 0.86226921 | ... AL13: =Y13*VLOOKUP(BX13,Exposure!$B$33:$C$53,2,FALSE)/VLOOKUP(BI13,Exposure!$B$33:$C$53,2,FALSE) -> 0.8686713 | AZ13: =$O13 -> 2016 | BA13: =$AZ13+BA$1-1 -> 2017 | BB13: =$AZ13+BB$1-1 -> 2018 | BC13: =$AZ13+BC$1-1 -> 2019 | BD13: =$AZ13+BD$1-1 -> 2020 | BE13: =$AZ13+BE$1-1 -> 2021 | BF13: =$AZ13+BF$1-1 -> 2022 | BG13: =$AZ13+BG$1-1 -> 2023 | BH13: =$AZ13+BH$1-1 -> 2024 | BI13: =$AZ13+BI$1-1 -> 2025 | BO13: 2027 | BP13: =$BO13+BP$1-1 -> 2028 | BQ13: =$BO13+BQ$1-1 -> 2029 | BR13: =$BO13+BR$1-1 -> 2030 | BS13: =$BO13+BS$1-1 -> 2031 | BT13: =$BO13+BT$1-1 -> 2032 | BU13: =$BO13+BU$1-1 -> 2033 | BV13: =$BO13+BV$1-1 -> 2034 | BW13: =$BO13+BW$1-1 -> 2035 | BX13: =$BO13+BX$1-1 -> 2036
A14: 42683 | B14: 1281489.4 | C14: 1290805.5 | D14: 1293569 | E14: 1387890 | F14: 1772318.7 | G14: 2235654.1 | H14: 2285067.1 | I14: 2344718.9 | J14: 2346425.9 | K14: 2346444.2 | O14: =YEAR($A13) -> 2016 | P14: =$B13 -> 48508.148 | Q14: =C13-B13 -> 10049.929 | R14: =D13-C13 -> 720401.64 | S14: =E13-D13 -> 49608.581 | T14: =F13-E13 -> 62.812292 | U14: =G13-F13 -> 2194.9828 | V14: =H13-G13 -> 383.59633 | W14: =I13-H13 -> 21.195405 | X14: =J13-I13 -> 20.271308 | Y14: =K13-J13 -> 33.647274 | AB14: =$O14 -> 2016 | AC14: =P14*VLOOKUP(BO14,Exposure!$B$33:$C$53,2,FALSE)/VLOOKUP(AZ14,Exposure!$B$33:$C$53,2,FALSE) -> 77897.51 | AD14: =Q14*VLOOKUP(BP14,Exposure!$B$33:$C$53,2,FALSE)/VLOOKUP(BA14,Exposure!$B$33:$C$53,2,FALSE) -> 16087.764 | AE14: =R14*VLOOKUP(BQ14,Exposure!$B$33:$C$53,2,FALSE)/VLOOKUP(BB14,Exposure!$B$33:$C$53,2,FALSE) -> 1150400.5 | AF14: =S14*VLOOKUP(BR14,Exposure!$B$33:$C$53,2,FALSE)/VLOOKUP(BC14,Exposure!$B$33:$C$53,2,FALSE) -> 79495.23 | AG14: =T14*VLOOKUP(BS14,Exposure!$B$33:$C$53,2,FALSE)/VLOOKUP(BD14,Exposure!$B$33:$C$53,2,FALSE) -> 101.69571 | AH14: =U14*VLOOKUP(BT14,Exposure!$B$33:$C$53,2,FALSE)/VLOOKUP(BE14,Exposure!$B$33:$C$53,2,FALSE) -> 3531.8575 | AI14: =V14*VLOOKUP(BU14,Exposure!$B$33:$C$53,2,FALSE)/VLOOKUP(BF14,Exposure!$B$33:$C$53,2,FALSE) -> 574.00223 | AJ14: =W14*VLOOKUP(BV14,Exposure!$B$33:$C$53,2,FALSE)/VLOOKUP(BG14,Exposure!$B$33:$C$53,2,FALSE) -> 31.021225 | ... AL14: =Y14*VLOOKUP(BX14,Exposure!$B$33:$C$53,2,FALSE)/VLOOKUP(BI14,Exposure!$B$33:$C$53,2,FALSE) -> 48.299313 | AZ14: =$O14 -> 2016 | BA14: =$AZ14+BA$1-1 -> 2017 | BB14: =$AZ14+BB$1-1 -> 2018 | BC14: =$AZ14+BC$1-1 -> 2019 | BD14: =$AZ14+BD$1-1 -> 2020 | BE14: =$AZ14+BE$1-1 -> 2021 | BF14: =$AZ14+BF$1-1 -> 2022 | BG14: =$AZ14+BG$1-1 -> 2023 | BH14: =$AZ14+BH$1-1 -> 2024 | BI14: =$AZ14+BI$1-1 -> 2025 | BO14: 2027 | BP14: =$BO14+BP$1-1 -> 2028 | BQ14: =$BO14+BQ$1-1 -> 2029 | BR14: =$BO14+BR$1-1 -> 2030 | BS14: =$BO14+BS$1-1 -> 2031 | BT14: =$BO14+BT$1-1 -> 2032 | BU14: =$BO14+BU$1-1 -> 2033 | BV14: =$BO14+BV$1-1 -> 2034 | BW14: =$BO14+BW$1-1 -> 2035 | BX14: =$BO14+BX$1-1 -> 2036
A15: 42721 | B15: 408506.28 | C15: 841725.92 | D15: 847014.85 | E15: 882491.85 | F15: 1036788.2 | G15: 1162665.9 | H15: 1324549.6 | I15: 1469476.4 | J15: 2387942.9 | K15: 2397781.8 | O15: =YEAR($A14) -> 2016 | P15: =$B14 -> 1281489.4 | Q15: =C14-B14 -> 9316.0929 | R15: =D14-C14 -> 2763.5707 | S15: =E14-D14 -> 94320.971 | T15: =F14-E14 -> 384428.67 | U15: =G14-F14 -> 463335.46 | V15: =H14-G14 -> 49412.965 | W15: =I14-H14 -> 59651.859 | X15: =J14-I14 -> 1706.9217 | Y15: =K14-J14 -> 18.319925 | AB15: =$O15 -> 2016 | AC15: =P15*VLOOKUP(BO15,Exposure!$B$33:$C$53,2,FALSE)/VLOOKUP(AZ15,Exposure!$B$33:$C$53,2,FALSE) -> 2057898.2 | AD15: =Q15*VLOOKUP(BP15,Exposure!$B$33:$C$53,2,FALSE)/VLOOKUP(BA15,Exposure!$B$33:$C$53,2,FALSE) -> 14913.05 | AE15: =R15*VLOOKUP(BQ15,Exposure!$B$33:$C$53,2,FALSE)/VLOOKUP(BB15,Exposure!$B$33:$C$53,2,FALSE) -> 4413.1122 | AF15: =S15*VLOOKUP(BR15,Exposure!$B$33:$C$53,2,FALSE)/VLOOKUP(BC15,Exposure!$B$33:$C$53,2,FALSE) -> 151144.56 | AG15: =T15*VLOOKUP(BS15,Exposure!$B$33:$C$53,2,FALSE)/VLOOKUP(BD15,Exposure!$B$33:$C$53,2,FALSE) -> 622405.96 | AH15: =U15*VLOOKUP(BT15,Exposure!$B$33:$C$53,2,FALSE)/VLOOKUP(BE15,Exposure!$B$33:$C$53,2,FALSE) -> 745534.24 | AI15: =V15*VLOOKUP(BU15,Exposure!$B$33:$C$53,2,FALSE)/VLOOKUP(BF15,Exposure!$B$33:$C$53,2,FALSE) -> 73940.103 | AJ15: =W15*VLOOKUP(BV15,Exposure!$B$33:$C$53,2,FALSE)/VLOOKUP(BG15,Exposure!$B$33:$C$53,2,FALSE) -> 87305.42 | ... AL15: =Y15*VLOOKUP(BX15,Exposure!$B$33:$C$53,2,FALSE)/VLOOKUP(BI15,Exposure!$B$33:$C$53,2,FALSE) -> 26.297518 | AZ15: =$O15 -> 2016 | BA15: =$AZ15+BA$1-1 -> 2017 | BB15: =$AZ15+BB$1-1 -> 2018 | BC15: =$AZ15+BC$1-1 -> 2019 | BD15: =$AZ15+BD$1-1 -> 2020 | BE15: =$AZ15+BE$1-1 -> 2021 | BF15: =$AZ15+BF$1-1 -> 2022 | BG15: =$AZ15+BG$1-1 -> 2023 | BH15: =$AZ15+BH$1-1 -> 2024 | BI15: =$AZ15+BI$1-1 -> 2025 | BO15: 2027 | BP15: =$BO15+BP$1-1 -> 2028 | BQ15: =$BO15+BQ$1-1 -> 2029 | BR15: =$BO15+BR$1-1 -> 2030 | BS15: =$BO15+BS$1-1 -> 2031 | BT15: =$BO15+BT$1-1 -> 2032 | BU15: =$BO15+BU$1-1 -> 2033 | BV15: =$BO15+BV$1-1 -> 2034 | BW15: =$BO15+BW$1-1 -> 2035 | BX15: =$BO15+BX$1-1 -> 2036
A16: 42761 | B16: 590333.35 | C16: 604906.01 | D16: 1968378.3 | E16: 2262789 | F16: 2505929.8 | G16: 2958402.6 | H16: 2959750 | I16: 2960125.9 | J16: 2960133.4 | O16: =YEAR($A15) -> 2016 | P16: =$B15 -> 408506.28 | Q16: =C15-B15 -> 433219.64 | R16: =D15-C15 -> 5288.9258 | S16: =E15-D15 -> 35477.007 | T16: =F15-E15 -> 154296.37 | U16: =G15-F15 -> 125877.66 | V16: =H15-G15 -> 161883.73 | W16: =I15-H15 -> 144926.75 | X16: =J15-I15 -> 918466.52 | Y16: =K15-J15 -> 9838.8824 | AB16: =$O16 -> 2016 | AC16: =P16*VLOOKUP(BO16,Exposure!$B$33:$C$53,2,FALSE)/VLOOKUP(AZ16,Exposure!$B$33:$C$53,2,FALSE) -> 656005.71 | AD16: =Q16*VLOOKUP(BP16,Exposure!$B$33:$C$53,2,FALSE)/VLOOKUP(BA16,Exposure!$B$33:$C$53,2,FALSE) -> 693490.97 | AE16: =R16*VLOOKUP(BQ16,Exposure!$B$33:$C$53,2,FALSE)/VLOOKUP(BB16,Exposure!$B$33:$C$53,2,FALSE) -> 8445.8208 | AF16: =S16*VLOOKUP(BR16,Exposure!$B$33:$C$53,2,FALSE)/VLOOKUP(BC16,Exposure!$B$33:$C$53,2,FALSE) -> 56850.1 | AG16: =T16*VLOOKUP(BS16,Exposure!$B$33:$C$53,2,FALSE)/VLOOKUP(BD16,Exposure!$B$33:$C$53,2,FALSE) -> 249812.23 | AH16: =U16*VLOOKUP(BT16,Exposure!$B$33:$C$53,2,FALSE)/VLOOKUP(BE16,Exposure!$B$33:$C$53,2,FALSE) -> 202544.62 | AI16: =V16*VLOOKUP(BU16,Exposure!$B$33:$C$53,2,FALSE)/VLOOKUP(BF16,Exposure!$B$33:$C$53,2,FALSE) -> 242238.03 | AJ16: =W16*VLOOKUP(BV16,Exposure!$B$33:$C$53,2,FALSE)/VLOOKUP(BG16,Exposure!$B$33:$C$53,2,FALSE) -> 212112.26 | ... AL16: =Y16*VLOOKUP(BX16,Exposure!$B$33:$C$53,2,FALSE)/VLOOKUP(BI16,Exposure!$B$33:$C$53,2,FALSE) -> 14123.322 | AZ16: =$O16 -> 2016 | BA16: =$AZ16+BA$1-1 -> 2017 | BB16: =$AZ16+BB$1-1 -> 2018 | BC16: =$AZ16+BC$1-1 -> 2019 | BD16: =$AZ16+BD$1-1 -> 2020 | BE16: =$AZ16+BE$1-1 -> 2021 | BF16: =$AZ16+BF$1-1 -> 2022 | BG16: =$AZ16+BG$1-1 -> 2023 | BH16: =$AZ16+BH$1-1 -> 2024 | BI16: =$AZ16+BI$1-1 -> 2025 | BO16: 2027 | BP16: =$BO16+BP$1-1 -> 2028 | BQ16: =$BO16+BQ$1-1 -> 2029 | BR16: =$BO16+BR$1-1 -> 2030 | BS16: =$BO16+BS$1-1 -> 2031 | BT16: =$BO16+BT$1-1 -> 2032 | BU16: =$BO16+BU$1-1 -> 2033 | BV16: =$BO16+BV$1-1 -> 2034 | BW16: =$BO16+BW$1-1 -> 2035 | BX16: =$BO16+BX$1-1 -> 2036
A17: 42775 | B17: 297429.69 | C17: 324197.87 | D17: 330954.1 | E17: 1212831 | F17: 1215271.7 | G17: 1231003.8 | H17: 1233298.6 | I17: 1250468.7 | J17: 1277885.7 | O17: =YEAR($A16) -> 2017 | P17: =$B16 -> 590333.35 | Q17: =C16-B16 -> 14572.665 | R17: =D16-C16 -> 1363472.3 | S17: =E16-D16 -> 294410.67 | T17: =F16-E16 -> 243140.79 | U17: =G16-F16 -> 452472.82 | V17: =H16-G16 -> 1347.4442 | W17: =I16-H16 -> 375.90144 | X17: =J16-I16 -> 7.5121361 | AB17: =$O17 -> 2017 | AC17: =P17*VLOOKUP(BO17,Exposure!$B$33:$C$53,2,FALSE)/VLOOKUP(AZ17,Exposure!$B$33:$C$53,2,FALSE) -> 914807.4 | AD17: =Q17*VLOOKUP(BP17,Exposure!$B$33:$C$53,2,FALSE)/VLOOKUP(BA17,Exposure!$B$33:$C$53,2,FALSE) -> 22527.503 | AE17: =R17*VLOOKUP(BQ17,Exposure!$B$33:$C$53,2,FALSE)/VLOOKUP(BB17,Exposure!$B$33:$C$53,2,FALSE) -> 2115096.8 | AF17: =S17*VLOOKUP(BR17,Exposure!$B$33:$C$53,2,FALSE)/VLOOKUP(BC17,Exposure!$B$33:$C$53,2,FALSE) -> 461435.71 | AG17: =T17*VLOOKUP(BS17,Exposure!$B$33:$C$53,2,FALSE)/VLOOKUP(BD17,Exposure!$B$33:$C$53,2,FALSE) -> 378729.87 | AH17: =U17*VLOOKUP(BT17,Exposure!$B$33:$C$53,2,FALSE)/VLOOKUP(BE17,Exposure!$B$33:$C$53,2,FALSE) -> 655437.55 | AI17: =V17*VLOOKUP(BU17,Exposure!$B$33:$C$53,2,FALSE)/VLOOKUP(BF17,Exposure!$B$33:$C$53,2,FALSE) -> 1909.0956 | AJ17: =W17*VLOOKUP(BV17,Exposure!$B$33:$C$53,2,FALSE)/VLOOKUP(BG17,Exposure!$B$33:$C$53,2,FALSE) -> 525.74648 | AK17: =X17*VLOOKUP(BW17,Exposure!$B$33:$C$53,2,FALSE)/VLOOKUP(BH17,Exposure!$B$33:$C$53,2,FALSE) -> 10.438887 | AZ17: =$O17 -> 2017 | BA17: =$AZ17+BA$1-1 -> 2018 | BB17: =$AZ17+BB$1-1 -> 2019 | BC17: =$AZ17+BC$1-1 -> 2020 | BD17: =$AZ17+BD$1-1 -> 2021 | BE17: =$AZ17+BE$1-1 -> 2022 | BF17: =$AZ17+BF$1-1 -> 2023 | BG17: =$AZ17+BG$1-1 -> 2024 | BH17: =$AZ17+BH$1-1 -> 2025 | BO17: 2027 | BP17: =$BO17+BP$1-1 -> 2028 | BQ17: =$BO17+BQ$1-1 -> 2029 | BR17: =$BO17+BR$1-1 -> 2030 | BS17: =$BO17+BS$1-1 -> 2031 | BT17: =$BO17+BT$1-1 -> 2032 | BU17: =$BO17+BU$1-1 -> 2033 | BV17: =$BO17+BV$1-1 -> 2034 | BW17: =$BO17+BW$1-1 -> 2035
A18: 42832 | B18: 92188.352 | C18: 850262.73 | D18: 1281096.1 | E18: 1357000.1 | F18: 1357180.4 | G18: 1727536.7 | H18: 1730782.1 | I18: 1854340.6 | J18: 1858893.6 | O18: =YEAR($A17) -> 2017 | P18: =$B17 -> 297429.69 | Q18: =C17-B17 -> 26768.184 | R18: =D17-C17 -> 6756.2243 | S18: =E17-D17 -> 881876.87 | T18: =F17-E17 -> 2440.7151 | U18: =G17-F17 -> 15732.116 | V18: =H17-G17 -> 2294.8191 | W18: =I17-H17 -> 17170.086 | X18: =J17-I17 -> 27416.958 | AB18: =$O18 -> 2017 | AC18: =P18*VLOOKUP(BO18,Exposure!$B$33:$C$53,2,FALSE)/VLOOKUP(AZ18,Exposure!$B$33:$C$53,2,FALSE) -> 460910.57 | AD18: =Q18*VLOOKUP(BP18,Exposure!$B$33:$C$53,2,FALSE)/VLOOKUP(BA18,Exposure!$B$33:$C$53,2,FALSE) -> 41380.237 | AE18: =R18*VLOOKUP(BQ18,Exposure!$B$33:$C$53,2,FALSE)/VLOOKUP(BB18,Exposure!$B$33:$C$53,2,FALSE) -> 10480.645 | AF18: =S18*VLOOKUP(BR18,Exposure!$B$33:$C$53,2,FALSE)/VLOOKUP(BC18,Exposure!$B$33:$C$53,2,FALSE) -> 1382183.2 | AG18: =T18*VLOOKUP(BS18,Exposure!$B$33:$C$53,2,FALSE)/VLOOKUP(BD18,Exposure!$B$33:$C$53,2,FALSE) -> 3801.7962 | AH18: =U18*VLOOKUP(BT18,Exposure!$B$33:$C$53,2,FALSE)/VLOOKUP(BE18,Exposure!$B$33:$C$53,2,FALSE) -> 22789.036 | AI18: =V18*VLOOKUP(BU18,Exposure!$B$33:$C$53,2,FALSE)/VLOOKUP(BF18,Exposure!$B$33:$C$53,2,FALSE) -> 3251.3622 | AJ18: =W18*VLOOKUP(BV18,Exposure!$B$33:$C$53,2,FALSE)/VLOOKUP(BG18,Exposure!$B$33:$C$53,2,FALSE) -> 24014.573 | AK18: =X18*VLOOKUP(BW18,Exposure!$B$33:$C$53,2,FALSE)/VLOOKUP(BH18,Exposure!$B$33:$C$53,2,FALSE) -> 38098.688 | AZ18: =$O18 -> 2017 | BA18: =$AZ18+BA$1-1 -> 2018 | BB18: =$AZ18+BB$1-1 -> 2019 | BC18: =$AZ18+BC$1-1 -> 2020 | BD18: =$AZ18+BD$1-1 -> 2021 | BE18: =$AZ18+BE$1-1 -> 2022 | BF18: =$AZ18+BF$1-1 -> 2023 | BG18: =$AZ18+BG$1-1 -> 2024 | BH18: =$AZ18+BH$1-1 -> 2025 | BO18: 2027 | BP18: =$BO18+BP$1-1 -> 2028 | BQ18: =$BO18+BQ$1-1 -> 2029 | BR18: =$BO18+BR$1-1 -> 2030 | BS18: =$BO18+BS$1-1 -> 2031 | BT18: =$BO18+BT$1-1 -> 2032 | BU18: =$BO18+BU$1-1 -> 2033 | BV18: =$BO18+BV$1-1 -> 2034 | BW18: =$BO18+BW$1-1 -> 2035
A19: 42844 | B19: 36320.305 | C19: 212686.51 | D19: 497060.3 | E19: 744519.85 | F19: 1259933.8 | G19: 1259933.9 | H19: 1259934 | I19: 1259934 | J19: 1259934 | O19: =YEAR($A18) -> 2017 | P19: =$B18 -> 92188.352 | Q19: =C18-B18 -> 758074.38 | R19: =D18-C18 -> 430833.32 | S19: =E18-D18 -> 75903.999 | T19: =F18-E18 -> 180.34719 | U19: =G18-F18 -> 370356.26 | V19: =H18-G18 -> 3245.423 | W19: =I18-H18 -> 123558.56 | X19: =J18-I18 -> 4552.9831 | AB19: =$O19 -> 2017 | AC19: =P19*VLOOKUP(BO19,Exposure!$B$33:$C$53,2,FALSE)/VLOOKUP(AZ19,Exposure!$B$33:$C$53,2,FALSE) -> 142859.26 | AD19: =Q19*VLOOKUP(BP19,Exposure!$B$33:$C$53,2,FALSE)/VLOOKUP(BA19,Exposure!$B$33:$C$53,2,FALSE) -> 1171887.4 | AE19: =R19*VLOOKUP(BQ19,Exposure!$B$33:$C$53,2,FALSE)/VLOOKUP(BB19,Exposure!$B$33:$C$53,2,FALSE) -> 668333.49 | AF19: =S19*VLOOKUP(BR19,Exposure!$B$33:$C$53,2,FALSE)/VLOOKUP(BC19,Exposure!$B$33:$C$53,2,FALSE) -> 118965.85 | AG19: =T19*VLOOKUP(BS19,Exposure!$B$33:$C$53,2,FALSE)/VLOOKUP(BD19,Exposure!$B$33:$C$53,2,FALSE) -> 280.919 | AH19: =U19*VLOOKUP(BT19,Exposure!$B$33:$C$53,2,FALSE)/VLOOKUP(BE19,Exposure!$B$33:$C$53,2,FALSE) -> 536486.14 | AI19: =V19*VLOOKUP(BU19,Exposure!$B$33:$C$53,2,FALSE)/VLOOKUP(BF19,Exposure!$B$33:$C$53,2,FALSE) -> 4598.2037 | AJ19: =W19*VLOOKUP(BV19,Exposure!$B$33:$C$53,2,FALSE)/VLOOKUP(BG19,Exposure!$B$33:$C$53,2,FALSE) -> 172812.53 | AK19: =X19*VLOOKUP(BW19,Exposure!$B$33:$C$53,2,FALSE)/VLOOKUP(BH19,Exposure!$B$33:$C$53,2,FALSE) -> 6326.8392 | AZ19: =$O19 -> 2017 | BA19: =$AZ19+BA$1-1 -> 2018 | BB19: =$AZ19+BB$1-1 -> 2019 | BC19: =$AZ19+BC$1-1 -> 2020 | BD19: =$AZ19+BD$1-1 -> 2021 | BE19: =$AZ19+BE$1-1 -> 2022 | BF19: =$AZ19+BF$1-1 -> 2023 | BG19: =$AZ19+BG$1-1 -> 2024 | BH19: =$AZ19+BH$1-1 -> 2025 | BO19: 2027 | BP19: =$BO19+BP$1-1 -> 2028 | BQ19: =$BO19+BQ$1-1 -> 2029 | BR19: =$BO19+BR$1-1 -> 2030 | BS19: =$BO19+BS$1-1 -> 2031 | BT19: =$BO19+BT$1-1 -> 2032 | BU19: =$BO19+BU$1-1 -> 2033 | BV19: =$BO19+BV$1-1 -> 2034 | BW19: =$BO19+BW$1-1 -> 2035
A20: 42844 | B20: 100859.96 | C20: 1565441.6 | D20: 1662022 | E20: 2532525.6 | F20: 2592835.1 | G20: 2592972.2 | H20: 2615002.3 | I20: 2618178.7 | J20: 2618827.1 | O20: =YEAR($A19) -> 2017 | P20: =$B19 -> 36320.305 | Q20: =C19-B19 -> 176366.21 | R20: =D19-C19 -> 284373.78 | S20: =E19-D19 -> 247459.56 | T20: =F19-E19 -> 515413.95 | U20: =G19-F19 -> 0.11950152 | V20: =H19-G19 -> 0.0793357 | W20: =I19-H19 -> 0.00038990541 | X20: =J19-I19 -> 5.4949662e-05 | AB20: =$O20 -> 2017 | AC20: =P20*VLOOKUP(BO20,Exposure!$B$33:$C$53,2,FALSE)/VLOOKUP(AZ20,Exposure!$B$33:$C$53,2,FALSE) -> 56283.596 | AD20: =Q20*VLOOKUP(BP20,Exposure!$B$33:$C$53,2,FALSE)/VLOOKUP(BA20,Exposure!$B$33:$C$53,2,FALSE) -> 272639.92 | AE20: =R20*VLOOKUP(BQ20,Exposure!$B$33:$C$53,2,FALSE)/VLOOKUP(BB20,Exposure!$B$33:$C$53,2,FALSE) -> 441137.01 | AF20: =S20*VLOOKUP(BR20,Exposure!$B$33:$C$53,2,FALSE)/VLOOKUP(BC20,Exposure!$B$33:$C$53,2,FALSE) -> 387848.3 | AG20: =T20*VLOOKUP(BS20,Exposure!$B$33:$C$53,2,FALSE)/VLOOKUP(BD20,Exposure!$B$33:$C$53,2,FALSE) -> 802837.97 | AH20: =U20*VLOOKUP(BT20,Exposure!$B$33:$C$53,2,FALSE)/VLOOKUP(BE20,Exposure!$B$33:$C$53,2,FALSE) -> 0.17310605 | AI20: =V20*VLOOKUP(BU20,Exposure!$B$33:$C$53,2,FALSE)/VLOOKUP(BF20,Exposure!$B$33:$C$53,2,FALSE) -> 0.11240498 | AJ20: =W20*VLOOKUP(BV20,Exposure!$B$33:$C$53,2,FALSE)/VLOOKUP(BG20,Exposure!$B$33:$C$53,2,FALSE) -> 0.00054533284 | AK20: =X20*VLOOKUP(BW20,Exposure!$B$33:$C$53,2,FALSE)/VLOOKUP(BH20,Exposure!$B$33:$C$53,2,FALSE) -> 7.6358217e-05 | AZ20: =$O20 -> 2017 | BA20: =$AZ20+BA$1-1 -> 2018 | BB20: =$AZ20+BB$1-1 -> 2019 | BC20: =$AZ20+BC$1-1 -> 2020 | BD20: =$AZ20+BD$1-1 -> 2021 | BE20: =$AZ20+BE$1-1 -> 2022 | BF20: =$AZ20+BF$1-1 -> 2023 | BG20: =$AZ20+BG$1-1 -> 2024 | BH20: =$AZ20+BH$1-1 -> 2025 | BO20: 2027 | BP20: =$BO20+BP$1-1 -> 2028 | BQ20: =$BO20+BQ$1-1 -> 2029 | BR20: =$BO20+BR$1-1 -> 2030 | BS20: =$BO20+BS$1-1 -> 2031 | BT20: =$BO20+BT$1-1 -> 2032 | BU20: =$BO20+BU$1-1 -> 2033 | BV20: =$BO20+BV$1-1 -> 2034 | BW20: =$BO20+BW$1-1 -> 2035
A21: 42884 | B21: 192663.34 | C21: 249091.69 | D21: 500853.76 | E21: 590380.75 | F21: 1060433.2 | G21: 1060629 | H21: 1064819.5 | I21: 1065471.6 | J21: 1067758.8 | O21: =YEAR($A20) -> 2017 | P21: =$B20 -> 100859.96 | Q21: =C20-B20 -> 1464581.7 | R21: =D20-C20 -> 96580.406 | S21: =E20-D20 -> 870503.53 | T21: =F20-E20 -> 60309.578 | U21: =G20-F20 -> 137.01918 | V21: =H20-G20 -> 22030.195 | W21: =I20-H20 -> 3176.3218 | X21: =J20-I20 -> 648.40088 | AB21: =$O21 -> 2017 | AC21: =P21*VLOOKUP(BO21,Exposure!$B$33:$C$53,2,FALSE)/VLOOKUP(AZ21,Exposure!$B$33:$C$53,2,FALSE) -> 156297.18 | AD21: =Q21*VLOOKUP(BP21,Exposure!$B$33:$C$53,2,FALSE)/VLOOKUP(BA21,Exposure!$B$33:$C$53,2,FALSE) -> 2264058.6 | AE21: =R21*VLOOKUP(BQ21,Exposure!$B$33:$C$53,2,FALSE)/VLOOKUP(BB21,Exposure!$B$33:$C$53,2,FALSE) -> 149821.1 | AF21: =S21*VLOOKUP(BR21,Exposure!$B$33:$C$53,2,FALSE)/VLOOKUP(BC21,Exposure!$B$33:$C$53,2,FALSE) -> 1364357.5 | AG21: =T21*VLOOKUP(BS21,Exposure!$B$33:$C$53,2,FALSE)/VLOOKUP(BD21,Exposure!$B$33:$C$53,2,FALSE) -> 93941.616 | AH21: =U21*VLOOKUP(BT21,Exposure!$B$33:$C$53,2,FALSE)/VLOOKUP(BE21,Exposure!$B$33:$C$53,2,FALSE) -> 198.48156 | AI21: =V21*VLOOKUP(BU21,Exposure!$B$33:$C$53,2,FALSE)/VLOOKUP(BF21,Exposure!$B$33:$C$53,2,FALSE) -> 31212.98 | AJ21: =W21*VLOOKUP(BV21,Exposure!$B$33:$C$53,2,FALSE)/VLOOKUP(BG21,Exposure!$B$33:$C$53,2,FALSE) -> 4442.4943 | AK21: =X21*VLOOKUP(BW21,Exposure!$B$33:$C$53,2,FALSE)/VLOOKUP(BH21,Exposure!$B$33:$C$53,2,FALSE) -> 901.01982 | AZ21: =$O21 -> 2017 | BA21: =$AZ21+BA$1-1 -> 2018 | BB21: =$AZ21+BB$1-1 -> 2019 | BC21: =$AZ21+BC$1-1 -> 2020 | BD21: =$AZ21+BD$1-1 -> 2021 | BE21: =$AZ21+BE$1-1 -> 2022 | BF21: =$AZ21+BF$1-1 -> 2023 | BG21: =$AZ21+BG$1-1 -> 2024 | BH21: =$AZ21+BH$1-1 -> 2025 | BO21: 2027 | BP21: =$BO21+BP$1-1 -> 2028 | BQ21: =$BO21+BQ$1-1 -> 2029 | BR21: =$BO21+BR$1-1 -> 2030 | BS21: =$BO21+BS$1-1 -> 2031 | BT21: =$BO21+BT$1-1 -> 2032 | BU21: =$BO21+BU$1-1 -> 2033 | BV21: =$BO21+BV$1-1 -> 2034 | BW21: =$BO21+BW$1-1 -> 2035
A22: 42920 | B22: 1056983.6 | C22: 1167275.9 | D22: 2062388.1 | E22: 2166650.1 | F22: 3798380.1 | G22: 3883242.9 | H22: 3883968.5 | I22: 3883978 | J22: 3884107.8 | O22: =YEAR($A21) -> 2017 | P22: =$B21 -> 192663.34 | Q22: =C21-B21 -> 56428.344 | R22: =D21-C21 -> 251762.07 | S22: =E21-D21 -> 89526.998 | T22: =F21-E21 -> 470052.45 | U22: =G21-F21 -> 195.80013 | V22: =H21-G21 -> 4190.4946 | W22: =I21-H21 -> 652.06391 | X22: =J21-I21 -> 2287.235 | AB22: =$O22 -> 2017 | AC22: =P22*VLOOKUP(BO22,Exposure!$B$33:$C$53,2,FALSE)/VLOOKUP(AZ22,Exposure!$B$33:$C$53,2,FALSE) -> 298559.88 | AD22: =Q22*VLOOKUP(BP22,Exposure!$B$33:$C$53,2,FALSE)/VLOOKUP(BA22,Exposure!$B$33:$C$53,2,FALSE) -> 87231.105 | AE22: =R22*VLOOKUP(BQ22,Exposure!$B$33:$C$53,2,FALSE)/VLOOKUP(BB22,Exposure!$B$33:$C$53,2,FALSE) -> 390547.84 | AF22: =S22*VLOOKUP(BR22,Exposure!$B$33:$C$53,2,FALSE)/VLOOKUP(BC22,Exposure!$B$33:$C$53,2,FALSE) -> 140317.45 | AG22: =T22*VLOOKUP(BS22,Exposure!$B$33:$C$53,2,FALSE)/VLOOKUP(BD22,Exposure!$B$33:$C$53,2,FALSE) -> 732180.33 | AH22: =U22*VLOOKUP(BT22,Exposure!$B$33:$C$53,2,FALSE)/VLOOKUP(BE22,Exposure!$B$33:$C$53,2,FALSE) -> 283.62976 | AI22: =V22*VLOOKUP(BU22,Exposure!$B$33:$C$53,2,FALSE)/VLOOKUP(BF22,Exposure!$B$33:$C$53,2,FALSE) -> 5937.2069 | AJ22: =W22*VLOOKUP(BV22,Exposure!$B$33:$C$53,2,FALSE)/VLOOKUP(BG22,Exposure!$B$33:$C$53,2,FALSE) -> 911.99518 | AK22: =X22*VLOOKUP(BW22,Exposure!$B$33:$C$53,2,FALSE)/VLOOKUP(BH22,Exposure!$B$33:$C$53,2,FALSE) -> 3178.3486 | AZ22: =$O22 -> 2017 | BA22: =$AZ22+BA$1-1 -> 2018 | BB22: =$AZ22+BB$1-1 -> 2019 | BC22: =$AZ22+BC$1-1 -> 2020 | BD22: =$AZ22+BD$1-1 -> 2021 | BE22: =$AZ22+BE$1-1 -> 2022 | BF22: =$AZ22+BF$1-1 -> 2023 | BG22: =$AZ22+BG$1-1 -> 2024 | BH22: =$AZ22+BH$1-1 -> 2025 | BO22: 2027 | BP22: =$BO22+BP$1-1 -> 2028 | BQ22: =$BO22+BQ$1-1 -> 2029 | BR22: =$BO22+BR$1-1 -> 2030 | BS22: =$BO22+BS$1-1 -> 2031 | BT22: =$BO22+BT$1-1 -> 2032 | BU22: =$BO22+BU$1-1 -> 2033 | BV22: =$BO22+BV$1-1 -> 2034 | BW22: =$BO22+BW$1-1 -> 2035
A23: 42943 | B23: 321245.03 | C23: 356845.44 | D23: 397791.85 | E23: 796518.9 | F23: 1314135.2 | G23: 1389442 | H23: 1477040.5 | I23: 1479239.8 | J23: 1523440.9 | O23: =YEAR($A22) -> 2017 | P23: =$B22 -> 1056983.6 | Q23: =C22-B22 -> 110292.31 | R23: =D22-C22 -> 895112.16 | S23: =E22-D22 -> 104261.96 | T23: =F22-E22 -> 1631730 | U23: =G22-F22 -> 84862.845 | V23: =H22-G22 -> 725.57485 | W23: =I22-H22 -> 9.4653319 | X23: =J22-I22 -> 129.80258 | AB23: =$O23 -> 2017 | AC23: =P23*VLOOKUP(BO23,Exposure!$B$33:$C$53,2,FALSE)/VLOOKUP(AZ23,Exposure!$B$33:$C$53,2,FALSE) -> 1637949.9 | AD23: =Q23*VLOOKUP(BP23,Exposure!$B$33:$C$53,2,FALSE)/VLOOKUP(BA23,Exposure!$B$33:$C$53,2,FALSE) -> 170498 | AE23: =R23*VLOOKUP(BQ23,Exposure!$B$33:$C$53,2,FALSE)/VLOOKUP(BB23,Exposure!$B$33:$C$53,2,FALSE) -> 1388549.6 | AF23: =S23*VLOOKUP(BR23,Exposure!$B$33:$C$53,2,FALSE)/VLOOKUP(BC23,Exposure!$B$33:$C$53,2,FALSE) -> 163411.86 | AG23: =T23*VLOOKUP(BS23,Exposure!$B$33:$C$53,2,FALSE)/VLOOKUP(BD23,Exposure!$B$33:$C$53,2,FALSE) -> 2541675.1 | AH23: =U23*VLOOKUP(BT23,Exposure!$B$33:$C$53,2,FALSE)/VLOOKUP(BE23,Exposure!$B$33:$C$53,2,FALSE) -> 122929.58 | AI23: =V23*VLOOKUP(BU23,Exposure!$B$33:$C$53,2,FALSE)/VLOOKUP(BF23,Exposure!$B$33:$C$53,2,FALSE) -> 1028.0142 | AJ23: =W23*VLOOKUP(BV23,Exposure!$B$33:$C$53,2,FALSE)/VLOOKUP(BG23,Exposure!$B$33:$C$53,2,FALSE) -> 13.238483 | AK23: =X23*VLOOKUP(BW23,Exposure!$B$33:$C$53,2,FALSE)/VLOOKUP(BH23,Exposure!$B$33:$C$53,2,FALSE) -> 180.37406 | AZ23: =$O23 -> 2017 | BA23: =$AZ23+BA$1-1 -> 2018 | BB23: =$AZ23+BB$1-1 -> 2019 | BC23: =$AZ23+BC$1-1 -> 2020 | BD23: =$AZ23+BD$1-1 -> 2021 | BE23: =$AZ23+BE$1-1 -> 2022 | BF23: =$AZ23+BF$1-1 -> 2023 | BG23: =$AZ23+BG$1-1 -> 2024 | BH23: =$AZ23+BH$1-1 -> 2025 | BO23: 2027 | BP23: =$BO23+BP$1-1 -> 2028 | BQ23: =$BO23+BQ$1-1 -> 2029 | BR23: =$BO23+BR$1-1 -> 2030 | BS23: =$BO23+BS$1-1 -> 2031 | BT23: =$BO23+BT$1-1 -> 2032 | BU23: =$BO23+BU$1-1 -> 2033 | BV23: =$BO23+BV$1-1 -> 2034 | BW23: =$BO23+BW$1-1 -> 2035
A24: 43008 | B24: 2694.7167 | C24: 16477.935 | D24: 80432.26 | E24: 209615.05 | F24: 643984.99 | G24: 971640.13 | H24: 1011270.4 | I24: 1049042.2 | J24: 1061951.1 | O24: =YEAR($A23) -> 2017 | P24: =$B23 -> 321245.03 | Q24: =C23-B23 -> 35600.405 | R24: =D23-C23 -> 40946.412 | S24: =E23-D23 -> 398727.05 | T24: =F23-E23 -> 517616.35 | U24: =G23-F23 -> 75306.72 | V24: =H23-G23 -> 87598.486 | W24: =I23-H23 -> 2199.3282 | X24: =J23-I23 -> 44201.162 | AB24: =$O24 -> 2017 | AC24: =P24*VLOOKUP(BO24,Exposure!$B$33:$C$53,2,FALSE)/VLOOKUP(AZ24,Exposure!$B$33:$C$53,2,FALSE) -> 497815.91 | AD24: =Q24*VLOOKUP(BP24,Exposure!$B$33:$C$53,2,FALSE)/VLOOKUP(BA24,Exposure!$B$33:$C$53,2,FALSE) -> 55033.738 | AE24: =R24*VLOOKUP(BQ24,Exposure!$B$33:$C$53,2,FALSE)/VLOOKUP(BB24,Exposure!$B$33:$C$53,2,FALSE) -> 63518.435 | AF24: =S24*VLOOKUP(BR24,Exposure!$B$33:$C$53,2,FALSE)/VLOOKUP(BC24,Exposure!$B$33:$C$53,2,FALSE) -> 624932.85 | AG24: =T24*VLOOKUP(BS24,Exposure!$B$33:$C$53,2,FALSE)/VLOOKUP(BD24,Exposure!$B$33:$C$53,2,FALSE) -> 806268.56 | AH24: =U24*VLOOKUP(BT24,Exposure!$B$33:$C$53,2,FALSE)/VLOOKUP(BE24,Exposure!$B$33:$C$53,2,FALSE) -> 109086.89 | AI24: =V24*VLOOKUP(BU24,Exposure!$B$33:$C$53,2,FALSE)/VLOOKUP(BF24,Exposure!$B$33:$C$53,2,FALSE) -> 124111.92 | AJ24: =W24*VLOOKUP(BV24,Exposure!$B$33:$C$53,2,FALSE)/VLOOKUP(BG24,Exposure!$B$33:$C$53,2,FALSE) -> 3076.0432 | AK24: =X24*VLOOKUP(BW24,Exposure!$B$33:$C$53,2,FALSE)/VLOOKUP(BH24,Exposure!$B$33:$C$53,2,FALSE) -> 61422.068 | AZ24: =$O24 -> 2017 | BA24: =$AZ24+BA$1-1 -> 2018 | BB24: =$AZ24+BB$1-1 -> 2019 | BC24: =$AZ24+BC$1-1 -> 2020 | BD24: =$AZ24+BD$1-1 -> 2021 | BE24: =$AZ24+BE$1-1 -> 2022 | BF24: =$AZ24+BF$1-1 -> 2023 | BG24: =$AZ24+BG$1-1 -> 2024 | BH24: =$AZ24+BH$1-1 -> 2025 | BO24: 2027 | BP24: =$BO24+BP$1-1 -> 2028 | BQ24: =$BO24+BQ$1-1 -> 2029 | BR24: =$BO24+BR$1-1 -> 2030 | BS24: =$BO24+BS$1-1 -> 2031 | BT24: =$BO24+BT$1-1 -> 2032 | BU24: =$BO24+BU$1-1 -> 2033 | BV24: =$BO24+BV$1-1 -> 2034 | BW24: =$BO24+BW$1-1 -> 2035
A25: 43020 | B25: 41370.154 | C25: 110660.4 | D25: 516755.22 | E25: 521602.5 | F25: 551811.19 | G25: 601041.55 | H25: 729995.7 | I25: 733889.12 | J25: 735004.03 | O25: =YEAR($A24) -> 2017 | P25: =$B24 -> 2694.7167 | Q25: =C24-B24 -> 13783.219 | R25: =D24-C24 -> 63954.325 | S25: =E24-D24 -> 129182.79 | T25: =F24-E24 -> 434369.94 | U25: =G24-F24 -> 327655.14 | V25: =H24-G24 -> 39630.244 | W25: =I24-H24 -> 37771.846 | X25: =J24-I24 -> 12908.836 | AB25: =$O25 -> 2017 | AC25: =P25*VLOOKUP(BO25,Exposure!$B$33:$C$53,2,FALSE)/VLOOKUP(AZ25,Exposure!$B$33:$C$53,2,FALSE) -> 4175.8556 | AD25: =Q25*VLOOKUP(BP25,Exposure!$B$33:$C$53,2,FALSE)/VLOOKUP(BA25,Exposure!$B$33:$C$53,2,FALSE) -> 21307.118 | AE25: =R25*VLOOKUP(BQ25,Exposure!$B$33:$C$53,2,FALSE)/VLOOKUP(BB25,Exposure!$B$33:$C$53,2,FALSE) -> 99209.636 | AF25: =S25*VLOOKUP(BR25,Exposure!$B$33:$C$53,2,FALSE)/VLOOKUP(BC25,Exposure!$B$33:$C$53,2,FALSE) -> 202470.77 | AG25: =T25*VLOOKUP(BS25,Exposure!$B$33:$C$53,2,FALSE)/VLOOKUP(BD25,Exposure!$B$33:$C$53,2,FALSE) -> 676599.23 | AH25: =U25*VLOOKUP(BT25,Exposure!$B$33:$C$53,2,FALSE)/VLOOKUP(BE25,Exposure!$B$33:$C$53,2,FALSE) -> 474630.67 | AI25: =V25*VLOOKUP(BU25,Exposure!$B$33:$C$53,2,FALSE)/VLOOKUP(BF25,Exposure!$B$33:$C$53,2,FALSE) -> 56149.21 | AJ25: =W25*VLOOKUP(BV25,Exposure!$B$33:$C$53,2,FALSE)/VLOOKUP(BG25,Exposure!$B$33:$C$53,2,FALSE) -> 52828.782 | AK25: =X25*VLOOKUP(BW25,Exposure!$B$33:$C$53,2,FALSE)/VLOOKUP(BH25,Exposure!$B$33:$C$53,2,FALSE) -> 17938.158 | AZ25: =$O25 -> 2017 | BA25: =$AZ25+BA$1-1 -> 2018 | BB25: =$AZ25+BB$1-1 -> 2019 | BC25: =$AZ25+BC$1-1 -> 2020 | BD25: =$AZ25+BD$1-1 -> 2021 | BE25: =$AZ25+BE$1-1 -> 2022 | BF25: =$AZ25+BF$1-1 -> 2023 | BG25: =$AZ25+BG$1-1 -> 2024 | BH25: =$AZ25+BH$1-1 -> 2025 | BO25: 2027 | BP25: =$BO25+BP$1-1 -> 2028 | BQ25: =$BO25+BQ$1-1 -> 2029 | BR25: =$BO25+BR$1-1 -> 2030 | BS25: =$BO25+BS$1-1 -> 2031 | BT25: =$BO25+BT$1-1 -> 2032 | BU25: =$BO25+BU$1-1 -> 2033 | BV25: =$BO25+BV$1-1 -> 2034 | BW25: =$BO25+BW$1-1 -> 2035
A26: 43038 | B26: 123255.33 | C26: 134583.52 | D26: 154964.71 | E26: 2135490.8 | F26: 2151079.2 | G26: 2283965.2 | H26: 2284453.5 | I26: 2290084.6 | J26: 2290103.4 | O26: =YEAR($A25) -> 2017 | P26: =$B25 -> 41370.154 | Q26: =C25-B25 -> 69290.245 | R26: =D25-C25 -> 406094.82 | S26: =E25-D25 -> 4847.2831 | T26: =F25-E25 -> 30208.689 | U26: =G25-F25 -> 49230.363 | V26: =H25-G25 -> 128954.15 | W26: =I25-H25 -> 3893.4238 | X26: =J25-I25 -> 1114.91 | AB26: =$O26 -> 2017 | AC26: =P26*VLOOKUP(BO26,Exposure!$B$33:$C$53,2,FALSE)/VLOOKUP(AZ26,Exposure!$B$33:$C$53,2,FALSE) -> 64109.072 | AD26: =Q26*VLOOKUP(BP26,Exposure!$B$33:$C$53,2,FALSE)/VLOOKUP(BA26,Exposure!$B$33:$C$53,2,FALSE) -> 107113.98 | AE26: =R26*VLOOKUP(BQ26,Exposure!$B$33:$C$53,2,FALSE)/VLOOKUP(BB26,Exposure!$B$33:$C$53,2,FALSE) -> 629957.7 | AF26: =S26*VLOOKUP(BR26,Exposure!$B$33:$C$53,2,FALSE)/VLOOKUP(BC26,Exposure!$B$33:$C$53,2,FALSE) -> 7597.2434 | AG26: =T26*VLOOKUP(BS26,Exposure!$B$33:$C$53,2,FALSE)/VLOOKUP(BD26,Exposure!$B$33:$C$53,2,FALSE) -> 47054.765 | AH26: =U26*VLOOKUP(BT26,Exposure!$B$33:$C$53,2,FALSE)/VLOOKUP(BE26,Exposure!$B$33:$C$53,2,FALSE) -> 71313.516 | AI26: =V26*VLOOKUP(BU26,Exposure!$B$33:$C$53,2,FALSE)/VLOOKUP(BF26,Exposure!$B$33:$C$53,2,FALSE) -> 182705.75 | AJ26: =W26*VLOOKUP(BV26,Exposure!$B$33:$C$53,2,FALSE)/VLOOKUP(BG26,Exposure!$B$33:$C$53,2,FALSE) -> 5445.4536 | AK26: =X26*VLOOKUP(BW26,Exposure!$B$33:$C$53,2,FALSE)/VLOOKUP(BH26,Exposure!$B$33:$C$53,2,FALSE) -> 1549.2824 | AZ26: =$O26 -> 2017 | BA26: =$AZ26+BA$1-1 -> 2018 | BB26: =$AZ26+BB$1-1 -> 2019 | BC26: =$AZ26+BC$1-1 -> 2020 | BD26: =$AZ26+BD$1-1 -> 2021 | BE26: =$AZ26+BE$1-1 -> 2022 | BF26: =$AZ26+BF$1-1 -> 2023 | BG26: =$AZ26+BG$1-1 -> 2024 | BH26: =$AZ26+BH$1-1 -> 2025 | BO26: 2027 | BP26: =$BO26+BP$1-1 -> 2028 | BQ26: =$BO26+BQ$1-1 -> 2029 | BR26: =$BO26+BR$1-1 -> 2030 | BS26: =$BO26+BS$1-1 -> 2031 | BT26: =$BO26+BT$1-1 -> 2032 | BU26: =$BO26+BU$1-1 -> 2033 | BV26: =$BO26+BV$1-1 -> 2034 | BW26: =$BO26+BW$1-1 -> 2035
A27: 43053 | B27: 58611.766 | C27: 182911.28 | D27: 382492.92 | E27: 2067816.2 | F27: 2153530 | G27: 2876978.3 | H27: 3445373.1 | I27: 3446491.5 | J27: 3446675 | O27: =YEAR($A26) -> 2017 | P27: =$B26 -> 123255.33 | Q27: =C26-B26 -> 11328.186 | R27: =D26-C26 -> 20381.188 | S27: =E26-D26 -> 1980526.1 | T27: =F26-E26 -> 15588.406 | U27: =G26-F26 -> 132885.96 | V27: =H26-G26 -> 488.33437 | W27: =I26-H26 -> 5631.0549 | X27: =J26-I26 -> 18.825127 | AB27: =$O27 -> 2017 | AC27: =P27*VLOOKUP(BO27,Exposure!$B$33:$C$53,2,FALSE)/VLOOKUP(AZ27,Exposure!$B$33:$C$53,2,FALSE) -> 191002.07 | AD27: =Q27*VLOOKUP(BP27,Exposure!$B$33:$C$53,2,FALSE)/VLOOKUP(BA27,Exposure!$B$33:$C$53,2,FALSE) -> 17511.947 | AE27: =R27*VLOOKUP(BQ27,Exposure!$B$33:$C$53,2,FALSE)/VLOOKUP(BB27,Exposure!$B$33:$C$53,2,FALSE) -> 31616.474 | AF27: =S27*VLOOKUP(BR27,Exposure!$B$33:$C$53,2,FALSE)/VLOOKUP(BC27,Exposure!$B$33:$C$53,2,FALSE) -> 3104118.1 | AG27: =T27*VLOOKUP(BS27,Exposure!$B$33:$C$53,2,FALSE)/VLOOKUP(BD27,Exposure!$B$33:$C$53,2,FALSE) -> 24281.384 | AH27: =U27*VLOOKUP(BT27,Exposure!$B$33:$C$53,2,FALSE)/VLOOKUP(BE27,Exposure!$B$33:$C$53,2,FALSE) -> 192494.31 | AI27: =V27*VLOOKUP(BU27,Exposure!$B$33:$C$53,2,FALSE)/VLOOKUP(BF27,Exposure!$B$33:$C$53,2,FALSE) -> 691.88545 | AJ27: =W27*VLOOKUP(BV27,Exposure!$B$33:$C$53,2,FALSE)/VLOOKUP(BG27,Exposure!$B$33:$C$53,2,FALSE) -> 7875.7541 | AK27: =X27*VLOOKUP(BW27,Exposure!$B$33:$C$53,2,FALSE)/VLOOKUP(BH27,Exposure!$B$33:$C$53,2,FALSE) -> 26.159454 | AZ27: =$O27 -> 2017 | BA27: =$AZ27+BA$1-1 -> 2018 | BB27: =$AZ27+BB$1-1 -> 2019 | BC27: =$AZ27+BC$1-1 -> 2020 | BD27: =$AZ27+BD$1-1 -> 2021 | BE27: =$AZ27+BE$1-1 -> 2022 | BF27: =$AZ27+BF$1-1 -> 2023 | BG27: =$AZ27+BG$1-1 -> 2024 | BH27: =$AZ27+BH$1-1 -> 2025 | BO27: 2027 | BP27: =$BO27+BP$1-1 -> 2028 | BQ27: =$BO27+BQ$1-1 -> 2029 | BR27: =$BO27+BR$1-1 -> 2030 | BS27: =$BO27+BS$1-1 -> 2031 | BT27: =$BO27+BT$1-1 -> 2032 | BU27: =$BO27+BU$1-1 -> 2033 | BV27: =$BO27+BV$1-1 -> 2034 | BW27: =$BO27+BW$1-1 -> 2035
A28: 43055 | B28: 843676.92 | C28: 1758471.8 | D28: 1773841.3 | E28: 1837037 | F28: 3121214.3 | G28: 3127097.1 | H28: 3127119 | I28: 3127220.1 | J28: 3128570.4 | O28: =YEAR($A27) -> 2017 | P28: =$B27 -> 58611.766 | Q28: =C27-B27 -> 124299.51 | R28: =D27-C27 -> 199581.64 | S28: =E27-D27 -> 1685323.3 | T28: =F27-E27 -> 85713.765 | U28: =G27-F27 -> 723448.38 | V28: =H27-G27 -> 568394.77 | W28: =I27-H27 -> 1118.3888 | X28: =J27-I27 -> 183.46771 | AB28: =$O28 -> 2017 | AC28: =P28*VLOOKUP(BO28,Exposure!$B$33:$C$53,2,FALSE)/VLOOKUP(AZ28,Exposure!$B$33:$C$53,2,FALSE) -> 90827.459 | AD28: =Q28*VLOOKUP(BP28,Exposure!$B$33:$C$53,2,FALSE)/VLOOKUP(BA28,Exposure!$B$33:$C$53,2,FALSE) -> 192151.37 | AE28: =R28*VLOOKUP(BQ28,Exposure!$B$33:$C$53,2,FALSE)/VLOOKUP(BB28,Exposure!$B$33:$C$53,2,FALSE) -> 309602.55 | AF28: =S28*VLOOKUP(BR28,Exposure!$B$33:$C$53,2,FALSE)/VLOOKUP(BC28,Exposure!$B$33:$C$53,2,FALSE) -> 2641440.8 | AG28: =T28*VLOOKUP(BS28,Exposure!$B$33:$C$53,2,FALSE)/VLOOKUP(BD28,Exposure!$B$33:$C$53,2,FALSE) -> 133512.62 | AH28: =U28*VLOOKUP(BT28,Exposure!$B$33:$C$53,2,FALSE)/VLOOKUP(BE28,Exposure!$B$33:$C$53,2,FALSE) -> 1047964 | AI28: =V28*VLOOKUP(BU28,Exposure!$B$33:$C$53,2,FALSE)/VLOOKUP(BF28,Exposure!$B$33:$C$53,2,FALSE) -> 805317.2 | AJ28: =W28*VLOOKUP(BV28,Exposure!$B$33:$C$53,2,FALSE)/VLOOKUP(BG28,Exposure!$B$33:$C$53,2,FALSE) -> 1564.2105 | AK28: =X28*VLOOKUP(BW28,Exposure!$B$33:$C$53,2,FALSE)/VLOOKUP(BH28,Exposure!$B$33:$C$53,2,FALSE) -> 254.94729 | AZ28: =$O28 -> 2017 | BA28: =$AZ28+BA$1-1 -> 2018 | BB28: =$AZ28+BB$1-1 -> 2019 | BC28: =$AZ28+BC$1-1 -> 2020 | BD28: =$AZ28+BD$1-1 -> 2021 | BE28: =$AZ28+BE$1-1 -> 2022 | BF28: =$AZ28+BF$1-1 -> 2023 | BG28: =$AZ28+BG$1-1 -> 2024 | BH28: =$AZ28+BH$1-1 -> 2025 | BO28: 2027 | BP28: =$BO28+BP$1-1 -> 2028 | BQ28: =$BO28+BQ$1-1 -> 2029 | BR28: =$BO28+BR$1-1 -> 2030 | BS28: =$BO28+BS$1-1 -> 2031 | BT28: =$BO28+BT$1-1 -> 2032 | BU28: =$BO28+BU$1-1 -> 2033 | BV28: =$BO28+BV$1-1 -> 2034 | BW28: =$BO28+BW$1-1 -> 2035
